Workbook

Sheet 상품목록
A1: product_id | B1: cat1 | C1: cat2 | D1: sido | E1: gwon | F1: region | G1: name | H1: tagline | I1: list_price | J1: sale_price | K1: discount_pct | L1: basis | M1: option_count | N1: valid_from | O1: valid_to | P1: valid_days | Q1: badges | R1: issue_type | S1: issue_channel | T1: issue_medium | U1: usage_method | V1: max_qty | W1: refund_rule | X1: vendor_name | Y1: vendor_address | Z1: vendor_phone | AA1: external_link | AB1: ticket_div | AC1: priced | AD1: check | AE1: collected_at
A2: 243478 | B2: 삼성미라클안과 | C2: 라식·라섹 | D2: 서울;충남 | E2: 수도권;충청 | F2: 서울/천안 | G2: 삼성미라클안과 라식·라섹 | H2: 삼성미라클 평생시력 1:1 책임관리 프로그램 | I2: 1600000 | J2: 890000 | K2: 44 | L2: 미라클라섹 | M2: 3 | N2: 구매일 | P2: 0 | Q2: ;광고상품 | R2: 광고상품 | U2: 전화 예약 | V2: 10 | X2: 삼성미라클안과 | Z2: 010-2504-5792(이승민 실장) | AB2: 광고상품 | AC2: N | AE2: 2026-09-30T04:39:21
A3: 328990 | B3: 테마파크 | C3: 테마파크 | D3: 경기 | E3: 수도권 | F3: 용인 | G3: 한국민속촌 | H3: 조선시대로 떠나는 여행!! | I3: 39000 | J3: 19000 | K3: 51 | L3: 주중ㆍ주말공통 종일권 한국민속촌(~10/31) | M3: 1 | N3: 2026-10-01 | O3: 2026-10-31 | Q3: 모바일티켓;바로 사용가능 | R3: 즉시발송 | S3: 큐패스코리아 | T3: 알림톡 | U3: QR/바코드 제시 / 바로 입장 | V3: 10 | W3: 기한: 수령 후 7일 이내 | 수수료: 발송·취소 장당 1,000원 | 불가: 부분취소, 기간경과 | 접수: 유선(주중) | X3: 한국민속촌 | Y3: 경기 용인시 기흥구 민속촌로 90 한국민속촌 | Z3: 031-288-0000 | AA3: https://www.koreanfolk.co.kr/ | AB3: 바로 사용가능 | AC3: Y | AE3: 2026-09-30T04:39:24
A4: 326717 | B4: 테마파크 | C4: 놀이공원 | D4: 경기 | E4: 수도권 | F4: 과천 | G4: 서울랜드 | H4: 봄, 여름, 가을, 겨울 쉴 새 없이 터지는 즐거움 | I4: 52000 | J4: 17000 | K4: 67 | L4: AFTER 4 서울랜드(~11/1) | M4: 3 | N4: 구매일 | O4: 2026-11-01 | Q4: 모바일티켓;바로 사용가능 | R4: 즉시발송 | S4: 스마트인피니_발송 | T4: 알림톡/LMS 문자 | U4: 바로 입장 | 모바일 이용권 현장 제시 후 이용 가능(재발송 가능 상품) | V4: 10 | W4: 기한: 수령 후 7일 이내 | 수수료: 발송·취소 장당 1,000원 | 불가: 부분취소, 기간경과 | 접수: 유선 | X4: 서울랜드 | Y4: 경기 과천시 광명로 181 | Z4: 02-509-6000(주중 오전 10:00 ~ 17:00/주말 10:00 ~ 18:00) | AA4: www.seoulland.co.kr ; https://seoulland.co.kr/ | AB4: 바로 사용가능 | AC4: Y | AE4: 2026-09-30T04:39:26
A5: 329117 | B5: 테마파크 | C5: 놀이공원 | D5: 강원 | E5: 강원 | F5: 춘천 | G5: 레고랜드 | H5: 40 여개의 놀이기구, 다양한 퍼포먼스 쇼와 어트랙션들로 한가득 | I5: 66000 | J5: 36000 | K5: 45 | L5: 주중ㆍ주말 대소공통 레고랜드 2인 종일권(~11/15) | M5: 3 | N5: 2026-09-22 | O5: 2026-11-15 | Q5: 모바일티켓;바로 사용가능 | R5: 즉시발송 | T5: LMS 문자 | U5: QR/바코드 제시 / 바로 입장 | 모바일 이용권 현장 제시 후 이용 가능(재발송 가능 상품) | V5: 10 | W5: 기한: 수령 후 7일 이내 | 수수료: 발송·취소 장당 1,000원 | 불가: 부분취소, 기간경과 | 접수: 유선 | X5: 레고랜드코리아 | Y5: 강원 춘천시 하중도길 128 | Z5: 033-815-2300 | AA5: https://www.legoland.kr/ ; https://www.legoland.kr// | AB5: 바로 사용가능 | AC5: Y | AE5: 2026-09-30T04:39:29
A6: 330505 | B6: 테마파크 | C6: 놀이공원 | D6: 경북 | E6: 영남 | F6: 경주 | G6: 경주월드 | H6: 꿈, 사랑, 행복의 경주월드 | I6: 52000 | J6: 34000 | K6: 35 | L6: 대인 종일권 경주월드(~26/12/31) | M6: 2 | N6: 구매일 | O6: 2026-12-31 | Q6: 모바일티켓;바로 사용가능 | R6: 즉시발송 | T6: LMS 문자 | U6: 매표소 교환 / 바로 입장 | 모바일 이용권 현장 매표소 제시 후 이용 가능(재발송 가능 상품) | V6: 10 | W6: 기한: 수령 후 7일 이내 | 수수료: 발송·취소 장당 1,000원 | 불가: 부분취소, 기간경과 | 접수: 유선 | X6: 경주월드 | Y6: 경북 경주시 보문로 544 | Z6: 1544-8765 | AA6: https://www.gjw.co.kr/Contents/contents.php | AB6: 바로 사용가능 | AC6: Y | AE6: 2026-09-30T04:39:32
A7: 328545 | B7: 공연 | C7: 연극 | D7: 서울 | E7: 수도권 | F7: 서울 | G7: 연극 마트로시카 | H7: 까도 까도 빵빵 터지는 폭소 연발 씨츄에이숀 | I7: 66000 | J7: 36960 | K7: 44 | L7: 대소공통 관람권 마트로시카 | M7: 1 | N7: 구매일 | P7: 30 | Q7: 모바일티켓;예약필수 | R7: 예약필수 | U7: 매표소 교환 / 전화 예약 | 관람 예약 확정 후 현장 매표소 방문 및 발권하여 관람 가능 | V7: 100 | W7: 기한: 수령 후 7일 이내 | 수수료: 발송·취소 장당 1,000원 | 불가: 부분취소, 기간경과, 예약확정 후 | 접수: 유선(주중) | X7: 연극 마트로시카 | Y7: 서울특별시 중구 초동 18-5 명보아트홀 3층 | Z7: 010-4738-6960 | AB7: 예약필수 | AC7: Y | AE7: 2026-09-30T04:39:35
A8: 328609 | B8: 숙박 | C8: 숙박 | D8: 인천 | E8: 수도권 | F8: 강화 | G8: 엘리야리조트&풀빌라 숙박권 | H8: 전객실 오션뷰로 이루어진 강화도의 수려한 자연경관이 함께하는 리조트 | I8: 356800 | J8: 178400 | K8: 50 | L8: 디럭스 본관 주중 숙박권 엘리야리조트(~12/30) | M8: 12 | N8: 2026-09-10 | O8: 2026-12-30 | Q8: 모바일티켓;예약필수 | R8: 예약대기 | T8: LMS 문자 | U8: 전화 예약 | 사전예약 후 방문 | V8: 100 | W8: 수수료: D-11 100%, D-10 10%, D-9 10%, D-8 20%, D-7 30%, D-6 40%, D-5 50%, D-4 60%, D-3 70%, D-2 80%, D-1 90% | 접수: 유선(주중) | X8: 엘리야 리조트 | Y8: 인천 강화군 화도면 해안남로 2782-24 엘리야 리조트&풀빌라 | Z8: 032-937-5921 | AA8: http://www.elijahresort.com/ | AB8: 예약필수 | AC8: Y | AE8: 2026-09-30T04:39:37
A9: 328673 | B9: 숙박 | C9: 숙박 | D9: 강원 | E9: 강원 | F9: 강원 | G9: 에머슨 스위트 낙산 | H9: 가장 먼저 해가 뜨는 곳, 낙산의 푸른 바다를 가장 가까이에서 마주하세요 | I9: 240000 | J9: 120000 | K9: 50 | L9: 그랜드 디럭스 더블(하프 오션) 주중(일~목) | M9: 20 | N9: 2026-09-10 | O9: 2026-12-29 | Q9: 모바일티켓;예약필수 | R9: 예약대기 | T9: LMS 문자 | U9: 전화 예약 | 사전예약 후 방문 | V9: 100 | W9: 수수료: D-3 100%, D-2 50% | 접수: 유선(주중) | X9: 에머슨 스위트 낙산 | Y9: 강원 양양군 양양읍 해맞이길 88 | Z9: 0507-1345-9900 | AA9: https://www.emersonsuitesnaksan.com/ | AB9: 예약필수 | AC9: Y | AE9: 2026-09-30T04:39:39
A10: 329434 | B10: 워터파크 | C10: 워터파크 | D10: 경기 | E10: 수도권 | F10: 의정부 | G10: 장암 아일랜드캐슬 워터파크 1인 종일권 | H10: 사계절 내내 핫하게!! 수도권 HOT & NEW 워터파크 | I10: 45000 | J10: 21000 | K10: 53 | L10: (대소공통)장암 1인 종일권 (9/4~10/31)*구명조끼 미포함 | M10: 1 | N10: 2026-09-04 | O10: 2026-10-31 | Q10: 모바일티켓;바로 사용가능 | R10: 즉시발송 | T10: LMS 문자 | U10: 바로 입장 | V10: 10 | W10: 기한: 수령 후 7일 이내 | 수수료: 발송·취소 장당 1,000원 | 불가: 부분취소, 기간경과 | 접수: 유선 | X10: 장암아일랜드캐슬 워터파크 | Y10: 경기도 의정부시 장곡로 22 | Z10: 031-894-0331 | AA10: https://waterpark.islandcastle.net/ | AB10: 바로 사용가능 | AC10: Y | AE10: 2026-09-30T04:39:41
A11: 225306 | B11: 서울베스트의료의원 | C11: 건강검진 | D11: 서울 | E11: 수도권 | F11: 서울 | G11: 서울베스트의료의원 건강검진 | H11: 종합검진에 대한 모든 것 | I11: 0 | J11: 250000 | K11: 0 | L11: 종합건강검진 A형 | M11: 3 | N11: 구매일 | P11: 0 | Q11: ;광고상품 | R11: 광고상품 | U11: 전화 예약 | V11: 10 | X11: 서울베스트의료의원 | Y11: 서울 중구 다산로46길 17 두산위브더제니스 2층 서울베스트의료의원 | Z11: 02-2135-1357 | AA11: http://www.sbestmc.com/ | AB11: 광고상품 | AC11: N | AE11: 2026-09-30T04:39:43
A12: 324512 | B12: 레져 | C12: 액티비티 | D12: 강원 | E12: 강원 | F12: 영월 | G12: 동강흥국래프팅 | H12: 당일로 다녀오는 당신의 익스트림! 아름다운 영월 동강과 함께하세요. | I12: 15000 | J12: 10000 | K12: 33 | L12: 워터밤 물총 대여 동강흥국래프팅(~9/30) | M12: 10 | N12: 구매일 | O12: 2026-09-30 | Q12: 모바일티켓;예약필수 | R12: 예약필수 | S12: 큐패스코리아 | T12: 알림톡/LMS 문자 | U12: 전화 예약 / 바로 입장 | 사전 예약 후 방문 | V12: 100 | W12: 기한: 수령 후 7일 이내 | 수수료: 발송·취소 장당 1,000원, D-3 기본수수료, D-2 50% | 불가: 부분취소, 기간경과, 당일·노쇼 | 접수: 유선(주중) | X12: 동강흥국래프팅 | Y12: 강원도 영월군 영월읍 삼옥리 231-1 | Z12: 033-375-0846 | AA12: http://donggang114.co.kr/ | AB12: 예약필수 | AC12: Y | AE12: 2026-09-30T04:39:45
A13: 330442 | B13: 워터파크 | C13: 워터파크 | D13: 충남 | E13: 충청 | F13: 아산 | G13: 아산스파비스 | H13: 따뜻한 천연 온천수로 즐기는 물놀이 | I13: 50000 | J13: 20000 | K13: 60 | L13: 주중·주말공통이용권 아산스파비스(~26/12/31) | M13: 1 | N13: 2026-09-29 | O13: 2026-12-31 | Q13: 모바일티켓;바로 사용가능 | R13: 즉시발송 | T13: LMS 문자 | U13: QR/바코드 제시 / 매표소 교환 / 바로 입장 | LMS 바코드 문자 이용권 현장 매표소 제시 후 이용 가능(재발송 가능 상품) | V13: 20 | W13: 기한: 수령 후 7일 이내 | 수수료: 발송·취소 장당 1,000원 | 불가: 부분취소, 기간경과 | 접수: 유선 | X13: 아산스파비스 | Y13: 충남 아산시 음봉면 아산온천로157번길 67 아산스파비스 | Z13: 041-539-2000 | AA13: https://www.spavis.co.kr/ | AB13: 바로 사용가능 | AC13: Y | AE13: 2026-09-30T04:39:48
A14: 330001 | B14: 테마파크 | C14: 테마파크 | D14: 경기 | E14: 수도권 | F14: 부천 | G14: 볼베어파크 실내 키즈카페 | H14: 우리 아이의 취향저격 놀이터! | I14: 9000 | J14: 7650 | K14: 15 | L14: 평일 주말 통합권 대인권 부천 볼베어파크(~12/31) | M14: 3 | N14: 구매일 | O14: 2026-12-31 | Q14: 모바일티켓;바로 사용가능 | R14: 즉시발송 | S14: 엘에스컴퍼니 | T14: 알림톡 | U14: 매표소 교환 / 바로 입장 | 모바일 이용권 현장 매표소 제시 후 이용 가능(재발송 가능 상품) | V14: 20 | W14: 기한: 수령 후 7일 이내 | 수수료: 발송·취소 장당 1,000원 | 불가: 부분취소, 기간경과 | 접수: 유선(주중) | X14: 부천볼베어파크 | Y14: 경기 부천시 원미구 조마루로 2 웅진플레이도시 2층 볼베어파크 | Z14: 0507-1421-7789 | AB14: 바로 사용가능 | AC14: Y | AE14: 2026-09-30T04:39:50
A15: 327536 | B15: 테마파크 | C15: 테마파크 | D15: 부산 | E15: 영남 | F15: 부산 | G15: 세라젬 웰파크 부산기장점 | H15: 12가지 넘는 놀이 체험을 통해 부모님의 휴식을 제공! | I15: 5000 | J15: 4250 | K15: 15 | L15: 2시간 이용권 대인 세라젬 웰파크 부산기장점(~12/31) | M15: 3 | N15: 구매일 | O15: 2026-12-31 | Q15: 모바일티켓;바로 사용가능 | R15: 즉시발송 | S15: 엘에스컴퍼니 | T15: 알림톡 | U15: 매표소 교환 / 바로 입장 | 모바일 이용권 현장 매표소 제시 후 이용 가능(재발송 가능 상품) | V15: 20 | W15: 기한: 수령 후 7일 이내 | 수수료: 발송·취소 장당 1,000원 | 불가: 부분취소, 기간경과 | 접수: 유선(주중) | X15: 세라젬 웰파크 부산기장점 | Y15: 부산 기장군 기장읍 동부산관광1로 60 라우어 오시리아근린생활시설 1동 4층 | Z15: 070-8835-7979 | AB15: 바로 사용가능 | AC15: Y | AE15: 2026-09-30T04:39:52
A16: 329938 | B16: 테마파크 | C16: 테마파크 | D16: 경기 | E16: 수도권 | F16: 경기 하남 | G16: 세라젬 웰파크 위례점 | H16: 아이들을 위한 10여종의 놀이 공간! | I16: 7000 | J16: 5950 | K16: 15 | L16: 통합권 3시간 대인 세라젬 웰파크 위례점(~12/31) | M16: 3 | N16: 구매일 | O16: 2026-12-31 | Q16: 모바일티켓;바로 사용가능 | R16: 즉시발송 | S16: 엘에스컴퍼니 | T16: 알림톡 | U16: 매표소 교환 / 바로 입장 | 모바일 이용권 현장 매표소 제시 후 이용 가능(재발송 가능 상품) | V16: 20 | W16: 기한: 수령 후 7일 이내 | 수수료: 발송·취소 장당 1,000원 | 불가: 부분취소, 기간경과 | 접수: 유선(주중) | X16: 세라젬 웰파크 위례점 | Y16: 경기 하남시 위례대로 350 2층 201호~217호, 219호, 220호 | Z16: 070-4126-5265 | AB16: 바로 사용가능 | AC16: Y | AE16: 2026-09-30T04:39:55
A17: 313585 | B17: 레져 | C17: 액티비티 | D17: 인천 | E17: 수도권 | F17: 강화 | G17: 레포츠파크 | H17: 자연과 함께 숨쉬는 천상의 숲 | I17: 0 | J17: 43000 | K17: 0 | L17: 강화레포츠파크 서바이벌 + 3,4,5번 짚라인+고카트 트렉3바퀴 | M17: 2 | N17: 구매일 | P17: 30 | Q17: 모바일티켓;바로 사용가능 | R17: 즉시발송 | T17: LMS 문자 | U17: QR/바코드 제시 / 매표소 교환 / 바로 입장 | LMS 바코드 문자 이용권 현장 매표소 제시 후 이용 가능(재발송 가능 상품) | V17: 20 | W17: 기한: 수령 후 7일 이내 | 수수료: 발송·취소 장당 1,000원 | 불가: 부분취소, 기간경과 | 접수: 유선(주중) | X17: 강화레포츠파크 | Y17: 인천 강화군 불은면 삼성리 294-6 | Z17: 0507-1372-7481 | AA17: https://www.foresttrip.go.kr/indvz/main.do?hmpgId=ID04030105 | AB17: 바로 사용가능 | AC17: N | AE17: 2026-09-30T04:39:57
A18: 325961 | B18: 워터파크 | C18: 워터파크 | D18: 강원 | E18: 강원 | F18: 정선 | G18: 하이원 워터월드 | H18: 백두대산 1급 청정 계곡수를 그대로 옮겨 담은~ | I18: 64000 | J18: 28000 | K18: 56 | L18: 준성수기 주중 대인권 하이원워터월드(8/31~10/18) | M18: 4 | N18: 2026-08-31 | O18: 2026-10-18 | Q18: 모바일티켓;바로 사용가능 | R18: 즉시발송 | S18: 플레이스토리 | T18: 알림톡/LMS 문자/순차 발송 | U18: QR/바코드 제시 / 매표소 교환 / 바로 입장 | LMS 바코드 번호 키오스크에서 발권 후 이용 가능(재발송 가능 상품) | V18: 20 | W18: 기한: 수령 후 7일 이내 | 수수료: 발송·취소 장당 1,000원 | 불가: 부분취소, 기간경과 | 접수: 유선 | X18: 하이원 워터월드 | Y18: 강원도 정선군 사북읍 하이원길 175 | Z18: 1588-7789 | AA18: https://kangwonland.high1.com/waterworld/index.do | AB18: 바로 사용가능 | AC18: Y | AE18: 2026-09-30T04:39:59
A19: 326087 | B19: 워터파크 | C19: 워터파크 | D19: 충남 | E19: 충청 | F19: 예산 | G19: 스플라스 리솜 워터파크 | H19: 다양한 테마를 갖춘 온천테마파크! | I19: 40000 | J19: 27400 | K19: 32 | L19: 소인입장권 스플라스 워터파크(8/24~10/31) | M19: 2 | N19: 2026-08-24 | O19: 2026-10-31 | Q19: 모바일티켓;바로 사용가능 | R19: 즉시발송 | S19: 플레이스토리 | T19: 알림톡 | U19: 매표소 교환 / 바로 입장 | 모바일 이용권 현장 매표소 제시 후 이용 가능(재발송 가능 상품) | V19: 20 | W19: 기한: 수령 후 7일 이내 | 수수료: 발송·취소 장당 1,000원 | 불가: 부분취소, 기간경과 | 접수: 유선 | X19: 스플라스 리솜 워터파크 | Y19: 충남 예산군 덕산면 온천단지3로 45-7 | Z19: 041-330-8062 | AA19: https://www.resom.co.kr/spa/main/main.asp | AB19: 바로 사용가능 | AC19: Y | AE19: 2026-09-30T04:40:02
A20: 326024 | B20: 워터파크 | C20: 워터파크 | D20: 충북 | E20: 충청 | F20: 제천 | G20: 포레스트 리솜 해브나인 웰니스 스파 | H20: 숲 한가운데서 즐기는 노천 스파 | I20: 45000 | J20: 31000 | K20: 31 | L20: 소인이용권 포레스트리솜(8/24~10/31) | M20: 2 | N20: 2026-08-24 | O20: 2026-10-31 | Q20: 모바일티켓;바로 사용가능 | R20: 즉시발송 | S20: 플레이스토리 | T20: 알림톡/LMS 문자 | U20: 매표소 교환 / 바로 입장 | 알림톡 이용권 현장 매표소 제시 후 이용 가능(재발송 가능 상품) | V20: 10 | W20: 기한: 수령 후 7일 이내 | 수수료: 발송·취소 장당 1,000원 | 불가: 부분취소, 기간경과 | 접수: 유선 | X20: 포레스트 리솜 해브나인 스파 | Y20: 충청북도 제천시 백운면 금봉로 365 | Z20: 043-649-6014 | AA20: http://resom.co.kr/forest/theme/have9.asp?tab=0 | AB20: 바로 사용가능 | AC20: Y | AE20: 2026-09-30T04:40:04
A21: 326150 | B21: 워터파크 | C21: 워터파크 | D21: 충남 | E21: 충청 | F21: 태안 | G21: 아일랜드 리솜 오아식스 선셋스파 | H21: 단조로운 일상을 바꿀 오아식스 | I21: 40000 | J21: 34500 | K21: 14 | L21: 대인이용권 아일랜드리솜(8/24~10/31) | M21: 1 | N21: 2026-08-24 | O21: 2026-10-31 | Q21: 모바일티켓;바로 사용가능 | R21: 즉시발송 | S21: 플레이스토리 | T21: 알림톡/LMS 문자 | U21: QR/바코드 제시 / 매표소 교환 / 바로 입장 | LMS QR코드 문자 이용권 현장 매표소 제시 후 이용 가능(재발송 가능 상품) | V21: 20 | W21: 기한: 수령 후 7일 이내 | 수수료: 발송·취소 장당 1,000원 | 불가: 부분취소, 기간경과 | 접수: 유선 | X21: 아일랜드 리솜 오아식스 선셋스파 | Y21: 충남 태안군 안면읍 꽃지해안로 204 | Z21: 041-671-7060 | AA21: https://www.resom.co.kr/island/main/main.asp | AB21: 바로 사용가능 | AC21: Y | AE21: 2026-09-30T04:40:06
A22: 293316 | B22: 자동차 구매 | C22: 제네시스 | D22: 경기 | E22: 수도권 | F22: 분당오리대리점 | G22: 현대자동차(제네시스) 外 전차종 판매 | H22: GV90 26년 6월 출시, G80 26년 하반기 HEV출시, GV80 26년 하반기 HEV출시!!! | I22: 0 | J22: 0 | K22: 100 | L22: GENESIS GV70 (* 합리적 판매가격 상담문의 010-5014-3608) | M22: 4 | N22: 구매일 | P22: 0 | Q22: ;광고상품 | R22: 광고상품 | V22: 10 | X22: 현대자동차 분당오리대리점 | Y22: 경기도 성남시 분당구 성남대로 30, 동아그린프라자 1층(구미동) | Z22: 양원석 부장 010-5014-3608 / yws3608@naver.com | AA22: https://www.genesis.com/kr/ko/main.html | AB22: 광고상품 | AC22: N | AE22: 2026-09-30T04:40:08
A23: 311872 | B23: 테마파크 | C23: 테마파크 | D23: 부산 | E23: 영남 | F23: 부산 | G23: 부산영화체험박물관 + 씨네뮤지엄 PKG | H23: 영화의 도시, 부산에서 즐기는 영화탐험 | I23: 20000 | J23: 10800 | K23: 46 | L23: 대소공통 통합권 부산영화체험박물관PKG | M23: 1 | N23: 구매일 | P23: 60 | Q23: 모바일티켓;바로 사용가능 | R23: 즉시발송 | T23: LMS 문자 | U23: 매표소 교환 / 바로 입장 | 모바일 이용권 현장 매표소 제시 및 발권 후 이용 가능(재발송 가능 상품) | V23: 100 | W23: 기한: 수령 후 7일 이내 | 수수료: 발송·취소 장당 1,000원 | 불가: 부분취소, 기간경과 | 접수: 유선 | X23: 부산영화체험박물관 | Y23: 부산 중구 대청로126번길 12 부산영화체험박물관 | Z23: 051-468-8383 | AA23: https://busanbom.kr/ | AB23: 바로 사용가능 | AC23: Y | AE23: 2026-09-30T04:40:11
A24: 326465 | B24: 워터파크 | C24: 워터파크 | D24: 충남 | E24: 충청 | F24: 아산 | G24: 파라다이스 스파 도고 | H24: 프리미엄 온천 테마 워터파크! | I24: 55000 | J24: 28900 | K24: 47 | L24: 로우시즌 종일권 스파 도고(9/1~12/17) | M24: 1 | N24: 2026-09-01 | O24: 2026-12-17 | Q24: 모바일티켓;바로 사용가능 | R24: 즉시발송 | S24: 파라다이스 스파 도고 | T24: 알림톡 | U24: QR/바코드 제시 / 매표소 교환 / 바로 입장 | 알림톡 현장 매표소 또는 키오스크에서 발권 후 이용 가능(재발송 가능 상품) | V24: 10 | W24: 기한: 수령 후 7일 이내 | 수수료: 발송·취소 장당 1,000원 | 불가: 부분취소, 기간경과 | 접수: 유선 | X24: 파라다이스스파도고 | Y24: 충남 아산시 도고면 도고온천로 176 | Z24: 041-537-7100 | AA24: http://www.paradisespa.co.kr/ | AB24: 바로 사용가능 | AC24: Y | AE24: 2026-09-30T04:40:13
A25: 325709 | B25: 워터파크 | C25: 워터파크 | D25: 강원 | E25: 강원 | F25: 속초 | G25: 설악 워터피아 | H25: 설악 워터피아에서 즐기는 세계스파여행 | I25: 124000 | J25: 68000 | K25: 45 | L25: 2인 주간권 미들시즌 설악워터피아(8/24~10/11) | M25: 9 | N25: 2026-08-24 | O25: 2026-10-11 | Q25: 모바일티켓;바로 사용가능 | R25: 즉시발송 | S25: 엘에스컴퍼니 | T25: 알림톡 | U25: 바로 입장 | 모바일 이용권 현장 제시 후 이용 가능(재발송 가능 상품) | V25: 20 | W25: 기한: 수령 후 7일 이내 | 수수료: 발송·취소 장당 1,000원 | 불가: 부분취소, 기간경과 | 접수: 유선 | X25: 한화리조트 설악 워터피아 | Y25: 강원 속초시 장사동 24-1 | Z25: 033-630-5800 | AA25: https://www.hanwharesort.co.kr/irsweb/resort3/tpark/tp_intro.do?tp_cd=0100 | AB25: 바로 사용가능 | AC25: Y | AE25: 2026-09-30T04:40:16
A26: 330127 | B26: 워터파크 | C26: 워터파크 | D26: 경기 | E26: 수도권 | F26: 부천 | G26: 웅진플레이도시 워터파크 | H26: 언제나 신나는 웅플!파도파도~끝없는 즐거움 | I26: 60000 | J26: 27000 | K26: 55 | L26: 종일권 로우시즌 웅진플레이도시(~10/31) | M26: 1 | N26: 2026-09-07 | O26: 2026-10-31 | Q26: 모바일티켓;바로 사용가능 | R26: 즉시발송 | S26: 놀이의발견 | T26: 알림톡 | U26: 매표소 교환 / 바로 입장 | 알림톡 이용권 현장 매표소 제시 후 이용 가능(재발송 가능 상품) | V26: 10 | W26: 기한: 수령 후 7일 이내 | 수수료: 발송·취소 장당 1,000원 | 불가: 부분취소, 기간경과 | 접수: 유선 | X26: 웅진플레이도시 | Y26: 경기 부천시 조마루로 2 | Z26: 1577-5773 | AA26: http://www.playdoci.com/index.aspx | AB26: 바로 사용가능 | AC26: Y | AE26: 2026-09-30T04:40:19
A27: 319087 | B27: 테마파크 | C27: 테마파크 | D27: 부산 | E27: 영남 | F27: 부산 | G27: 런닝맨&다이나믹메이즈 | H27: 익사이팅 실내 어트랙션! | I27: 19000 | J27: 14000 | K27: 26 | L27: 이용권 런닝맨(60분)(~10/31) | M27: 5 | N27: 2025-12-01 | O27: 2026-10-31 | Q27: 모바일티켓;바로 사용가능 | R27: 즉시발송 | T27: LMS 문자 | U27: QR/바코드 제시 / 매표소 교환 / 바로 입장 | LMS 바코드 문자 이용권 현장 매표소 제시 후 이용 가능(재발송 가능 상품) | V27: 100 | W27: 기한: 구매 후 7일 이내 | 수수료: 발송·취소 장당 1,000원 | 불가: 부분취소, 기간경과 | 접수: 유선 | X27: 런닝맨+다이나믹메이즈 부산점 | Y27: 부산 부산진구 중앙대로 672 삼정타워 10층 | Z27: 051-520-3636 | AA27: http://www.running-man.co.kr/episode/episode2.php/ ; http://www.dynamicmaze.com/episode/busan.php | AB27: 바로 사용가능 | AC27: Y | AE27: 2026-09-30T04:40:22
A28: 319150 | B28: 테마파크 | C28: 테마파크 | D28: 서울 | E28: 수도권 | F28: 인사동 | G28: 런닝맨 or 다이나믹메이즈 | H28: 익사이팅 실내 어트랙션! | I28: 19000 | J28: 15000 | K28: 21 | L28: 런닝맨 1시간 이용권(~10/31) | M28: 3 | N28: 2025-12-01 | O28: 2026-10-31 | Q28: 모바일티켓;바로 사용가능 | R28: 즉시발송 | T28: LMS 문자 | U28: QR/바코드 제시 / 매표소 교환 / 바로 입장 | LMS 바코드 문자 이용권 현장 매표소 제시 후 이용 가능(재발송 가능 상품) | V28: 100 | W28: 기한: 구매 후 7일 이내 | 수수료: 발송·취소 장당 1,000원 | 불가: 부분취소, 기간경과 | 접수: 유선 | X28: 런닝맨&다이나믹메이즈 인사동점 | Y28: 서울 종로구 인사동길 12 대일빌딩 지하1층 | Z28: 02-2034-0600 | AA28: http://www.running-man.co.kr/ ; http://www.dynamicmaze.com/ | AB28: 바로 사용가능 | AC28: Y | AE28: 2026-09-30T04:40:24
A29: 292620 | B29: 테마파크 | C29: 테마파크 | D29: 경기 | E29: 수도권 | F29: 화성 | G29: 네이처스케이프 플러스 | H29: 새로운 모험이 기다리는 곳 | I29: 29500 | J29: 19000 | K29: 36 | L29: 주중종일·주말4시간 이용권 네이처스케이프플러스 | M29: 1 | N29: 구매일 | P29: 60 | Q29: 모바일티켓;바로 사용가능 | R29: 즉시발송 | T29: LMS 문자 | U29: QR/바코드 제시 / 매표소 교환 | LMS 바코드 문자 이용권 현장 매표소 제시 후 이용 가능(재발송 가능 상품) | V29: 50 | W29: 기한: 수령 후 7일 이내 | 수수료: 발송·취소 장당 1,000원 | 불가: 부분취소, 기간경과 | 접수: 유선 | X29: 네이처스케이프플러스 | Y29: 경기 화성시 동탄대로5길 21 라크몽 A동 4층~5층 | Z29: 031-1533-1245 | AA29: https://www.instagram.com/naturescapeplus/ | AB29: 바로 사용가능 | AC29: Y | AE29: 2026-09-30T04:40:27
A30: 327851 | B30: 테마파크 | C30: 테마파크 | D30: 강원 | E30: 강원 | F30: 홍천 | G30: 알파카월드 | H30: 세계 최초, 세계 유일의 알파카 테마파크! | I30: 18000 | J30: 14500 | K30: 19 | L30: 1인 입장권 알파카월드(~11/30) | M30: 1 | N30: 구매일 | O30: 2026-11-30 | Q30: 모바일티켓;바로 사용가능 | R30: 즉시발송 | S30: 엘에스컴퍼니 | T30: 알림톡 | U30: 매표소 교환 / 바로 입장 | 모바일 이용권 현장 매표소 제시 후 이용 가능(재발송 가능 상품) | V30: 20 | W30: 기한: 수령 후 7일 이내 | 수수료: 발송·취소 장당 1,000원 | 불가: 부분취소, 기간경과 | 접수: 유선(주중) | X30: 알파카월드 | Y30: 강원 홍천군 화촌면 덕밭재길 146-155 | Z30: 1899-2250 | AB30: 바로 사용가능 | AC30: Y | AE30: 2026-09-30T04:40:29
A31: 322055 | B31: 테마파크 | C31: 테마파크 | D31: 경기 | E31: 수도권 | F31: 경기 | G31: 허브아일랜드 | H31: 365일 꺼지지 않는 불빛동화축제 | I31: 8000 | J31: 7000 | K31: 13 | L31: 1인 주중 소인 입장권 허브아일랜드(~12/31) | M31: 4 | N31: 구매일 | O31: 2026-12-31 | Q31: 모바일티켓;바로 사용가능 | R31: 즉시발송 | S31: 엘에스컴퍼니 | T31: 알림톡 | U31: 매표소 교환 / 바로 입장 | 모바일 이용권 현장 매표소 제시 후 이용 가능(재발송 가능 상품) | V31: 20 | W31: 기한: 수령 후 7일 이내 | 수수료: 발송·취소 장당 1,000원 | 불가: 부분취소, 기간경과 | 접수: 유선(주중) | X31: 허브아일랜드 | Y31: 경기 포천시 신북면 청신로947번길 51 허브아일랜드 | Z31: 031-535-6494 | AB31: 바로 사용가능 | AC31: Y | AE31: 2026-09-30T04:40:31
A32: 327788 | B32: 테마파크 | C32: 테마파크 | D32: 대구 | E32: 영남 | F32: 대구 | G32: 드림닥터 대구점 의사직업체험 | H32: 15만명이 선택한 슬기로운 의사체험! | I32: 8000 | J32: 7200 | K32: 10 | L32: 보호자 이용권 대구 드림닥터(~10/31) | M32: 3 | N32: 구매일 | O32: 2026-10-31 | Q32: 모바일티켓;바로 사용가능 | R32: 즉시발송 | S32: 엘에스컴퍼니 | T32: 알림톡 | U32: 매표소 교환 / 바로 입장 | 모바일 이용권 현장 매표소 제시 후 이용 가능(재발송 가능 상품) | V32: 20 | W32: 기한: 수령 후 7일 이내 | 수수료: 발송·취소 장당 1,000원 | 불가: 부분취소, 기간경과 | 접수: 유선(주중) | X32: 드림닥터 대구점 | Y32: 대구 중구 공평로 36 동성로SK리더스뷰 3층 | Z32: 053-422-7999 | AB32: 바로 사용가능 | AC32: Y | AE32: 2026-09-30T04:40:34
A33: 327725 | B33: 테마파크 | C33: 테마파크 | D33: 대전 | E33: 충청 | F33: 대전 | G33: 드림닥터 대전점 의사직업체험 | H33: 15만명이 선택한 슬기로운 의사체험! | I33: 8000 | J33: 6400 | K33: 20 | L33: 보호자권 대전 드림닥터(~10/31) | M33: 4 | N33: 구매일 | O33: 2026-10-31 | Q33: 모바일티켓;바로 사용가능 | R33: 즉시발송 | S33: 엘에스컴퍼니 | T33: 알림톡 | U33: 매표소 교환 / 바로 입장 | 모바일 이용권 현장 매표소 제시 후 이용 가능(재발송 가능 상품) | V33: 20 | W33: 기한: 수령 후 7일 이내 | 수수료: 발송·취소 장당 1,000원 | 불가: 부분취소, 기간경과 | 접수: 유선(주중) | X33: 드림닥터 대전점 | Y33: 대전 유성구 학하북로 75-21 1층 | Z33: 0507-1420-2025 | AB33: 바로 사용가능 | AC33: Y | AE33: 2026-09-30T04:40:36
A34: 311557 | B34: 테마파크 | C34: 테마파크 | D34: 경기 | E34: 수도권 | F34: 과천 | G34: 원더파크 | H34: 오감을 만족시키는 체험형 미디어파크 | I34: 19000 | J34: 14500 | K34: 24 | L34: 소인이용권 원더파크 | M34: 2 | N34: 구매일 | P34: 60 | Q34: 모바일티켓;바로 사용가능 | R34: 즉시발송 | T34: LMS 문자 | U34: 매표소 교환 / 바로 입장 | 모바일 이용권 현장 매표소 제시 및 발권 후 이용 가능(재발송 가능 상품) | V34: 20 | W34: 기한: 수령 후 7일 이내 | 수수료: 발송·취소 장당 1,000원 | 불가: 부분취소, 기간경과 | 접수: 유선 | X34: 매직플로우 주식회사 | Y34: 서울특별시 강남구 역삼로77길 13, 1층(대치동, 비채빌딩) | Z34: 1555-5443 | AA34: https://www.magicflow.co.kr/park | AB34: 바로 사용가능 | AC34: Y | AE34: 2026-09-30T04:40:38
A35: 311746 | B35: 테마파크 | C35: 테마파크 | D35: 경북;경기 | E35: 영남;수도권 | F35: 경주/오산 | G35: 버드파크 | H35: 새와 사람과 자연의 이야기 | I35: 23000 | J35: 17800 | K35: 23 | L35: 대인이용권 오산버드파크 | M35: 4 | N35: 구매일 | P35: 60 | Q35: 모바일티켓;바로 사용가능 | R35: 즉시발송 | T35: LMS 문자 | U35: 매표소 교환 / 바로 입장 | 모바일 이용권 현장 매표소 제시 후 이용 가능(재발송 가능 상품) | V35: 100 | W35: 기한: 수령 후 7일 이내 | 수수료: 발송·취소 장당 1,000원 | 불가: 부분취소, 기간경과 | 접수: 유선 | X35: 경주버드파크 | Y35: 경북 경주시 보문로 74-14 | Z35: 054-777-7200 | AA35: http://www.birdparks.co.kr/ ; https://www.instagram.com/osanbirdpark/ | AB35: 바로 사용가능 | AC35: Y | AE35: 2026-09-30T04:40:41
A36: 319024 | B36: 테마파크 | C36: 테마파크 | D36: 경기 | E36: 수도권 | F36: 여주 | G36: 루덴시아 | H36: 갤러리형 유럽 테마파크 | I36: 27000 | J36: 14500 | K36: 46 | L36: 주중 대인입장권 루덴시아(~9/30) | M36: 4 | N36: 2025-11-01 | O36: 2026-09-30 | Q36: 모바일티켓;바로 사용가능 | R36: 즉시발송 | T36: LMS 문자 | U36: 매표소 교환 / 바로 입장 | 모바일 이용권 현장 매표소 제시 후 이용 가능(재발송 가능 상품) | V36: 20 | W36: 기한: 수령 후 7일 이내 | 수수료: 발송·취소 장당 1,000원 | 불가: 부분취소, 기간경과 | 접수: 유선 | X36: 루덴시아 | Y36: 경기 여주시 산북면 금품1로 177 여주 루덴시아 | Z36: 0507-1359-1025 | AA36: https://www.ludensia.com/ | AB36: 바로 사용가능 | AC36: Y | AE36: 2026-09-30T04:40:44
A37: 327284 | B37: 테마파크 | C37: 테마파크 | D37: 경남 | E37: 영남 | F37: 진주 | G37: 타이거펀치 키즈랜드 | H37: 진주에 오픈하는 1200평 규모의 대형 키즈랜드 | I37: 7000 | J37: 5000 | K37: 29 | L37: 주중 3시간 대인 입장권 타이거펀치(~10/31) | M37: 4 | N37: 2026-05-08 | O37: 2026-10-31 | Q37: 모바일티켓;바로 사용가능 | R37: 즉시발송 | S37: 엘에스컴퍼니 | T37: 알림톡 | U37: 매표소 교환 / 바로 입장 | 모바일 이용권 현장 매표소 제시 후 이용 가능(재발송 가능 상품) | V37: 20 | W37: 기한: 수령 후 7일 이내 | 수수료: 발송·취소 장당 1,000원 | 불가: 부분취소, 기간경과 | 접수: 유선(주중) | X37: 타이거펀치 키즈랜드 | Y37: 경남 진주시 명석면 진주대로 1982 | Z37: 055-763-3133 | AB37: 바로 사용가능 | AC37: Y | AE37: 2026-09-30T04:40:46
A38: 328862 | B38: 테마파크 | C38: 테마파크 | D38: 울산 | E38: 영남 | F38: 울산 | G38: 캐니언파크 | H38: 최대 규모의 애니멀 복합 테마파크 캐니언파크 울산점 오픈! | I38: 20000 | J38: 10000 | K38: 50 | L38: 평일/주말 유아입장권+실내놀이동산PKG 캐니언파크(~12/31) | M38: 5 | N38: 구매일 | O38: 2026-12-31 | Q38: 모바일티켓;바로 사용가능 | R38: 즉시발송 | S38: 엘에스컴퍼니 | T38: 알림톡 | U38: 매표소 교환 / 바로 입장 | 모바일 이용권 현장 매표소 제시 후 이용 가능(재발송 가능 상품) | V38: 20 | W38: 기한: 수령 후 7일 이내 | 수수료: 발송·취소 장당 1,000원 | 불가: 부분취소, 기간경과 | 접수: 유선(주중) | X38: 캐니언파크 | Y38: 울산 중구 만남의거리 15 3층, 4층 | Z38: 052-939-2100 | AB38: 바로 사용가능 | AC38: Y | AE38: 2026-09-30T04:40:49
A39: 325394 | B39: 테마파크 | C39: 테마파크 | D39: 경북 | E39: 영남 | F39: 경주 | G39: 원더스페이스 보문점 | H39: 원더스페이스에서 즐기는 복합 놀이 시설 테마파크! | I39: 50000 | J39: 23000 | K39: 54 | L39: 통합이용권A 원더스페이스(~10/31) | M39: 1 | N39: 구매일 | O39: 2026-10-31 | Q39: 모바일티켓;바로 사용가능 | R39: 즉시발송 | S39: 엘에스컴퍼니 | T39: 알림톡 | U39: 매표소 교환 / 바로 입장 | 모바일 이용권 현장 매표소 제시 후 이용 가능(재발송 가능 상품) | V39: 20 | W39: 기한: 수령 후 7일 이내 | 수수료: 발송·취소 장당 1,000원 | 불가: 부분취소, 기간경과 | 접수: 유선(주중) | X39: 원더스페이스 보문점 | Y39: 경북 경주시 보문로 391 원더스페이스 보문점 | Z39: 054-749-8999 | AB39: 바로 사용가능 | AC39: Y | AE39: 2026-09-30T04:40:51
A40: 326906 | B40: 테마파크 | C40: 테마파크 | D40: 경북 | E40: 영남 | F40: 청도 | G40: 프로방스 | H40: 여름숲속 빛축제! | I40: 14900 | J40: 8900 | K40: 40 | L40: 입장권 프로방스(~9/30) | M40: 1 | N40: 구매일 | O40: 2026-09-30 | Q40: 모바일티켓;바로 사용가능 | R40: 즉시발송 | S40: 엘에스컴퍼니 | T40: 알림톡 | U40: 매표소 교환 / 바로 입장 | 모바일 이용권 현장 매표소 제시 후 이용 가능(재발송 가능 상품) | V40: 20 | W40: 기한: 수령 후 7일 이내 | 수수료: 발송·취소 장당 1,000원 | 불가: 부분취소, 기간경과 | 접수: 유선(주중) | X40: 청도 프로방스 | Y40: 경북 청도군 화양읍 이슬미로 272-23 | Z40: 054-372-5050 | AB40: 바로 사용가능 | AC40: Y | AE40: 2026-09-30T04:40:54
...

Sheet 옵션
A1: product_id | B1: option_id | C1: cat1 | D1: cat2 | E1: region | F1: name | G1: option | H1: detail_div | I1: week_div | J1: time_div | K1: list_price | L1: sale_price | M1: discount_pct | N1: calc_discount_pct | O1: min_ticket_unit | P1: start_div | Q1: start_date | R1: end_div | S1: end_date | T1: is_basis
A2: 243478 | B2: 2311913 | C2: 삼성미라클안과 | D2: 라식·라섹 | E2: 서울/천안 | F2: 삼성미라클안과 라식·라섹 | G2: 미라클라섹(*예약문의 : 010-2504-5792) | K2: 1600000 | L2: 890000 | M2: 44 | N2: 44.4 | O2: 1 | P2: 구매일 | Q2: 0 | R2: 구매일 | S2: 0 | T2: TRUE
A3: 243478 | B3: 2311914 | C3: 삼성미라클안과 | D3: 라식·라섹 | E3: 서울/천안 | F3: 삼성미라클안과 라식·라섹 | G3: 양손스마일라식(*예약문의 : 010-2504-5792) | K3: 3100000 | L3: 2100000 | M3: 32 | N3: 32.3 | O3: 1 | P3: 구매일 | Q3: 0 | R3: 구매일 | S3: 0 | T3: FALSE
A4: 243478 | B4: 2311912 | C4: 삼성미라클안과 | D4: 라식·라섹 | E4: 서울/천안 | F4: 삼성미라클안과 라식·라섹 | G4: 렌즈삽입술(*예약문의 : 010-2504-5792) | K4: 6500000 | L4: 4990000 | M4: 23 | N4: 23.2 | O4: 1 | P4: 구매일 | Q4: 0 | R4: 구매일 | S4: 0 | T4: FALSE
A5: 328990 | B5: 4264809 | C5: 테마파크 | D5: 테마파크 | E5: 용인 | F5: 한국민속촌 | G5: 주중ㆍ주말공통 종일권 한국민속촌(~10/31) | H5: 대소공통 | I5: 주중+주말 | J5: 종일 | K5: 39000 | L5: 19000 | M5: 51 | N5: 51.3 | O5: 1 | P5: 날짜지정 | Q5: 2026-10-01 | R5: 날짜지정 | S5: 2026-10-31 | T5: TRUE
A6: 326717 | B6: 4201015 | C6: 테마파크 | D6: 놀이공원 | E6: 과천 | F6: 서울랜드 | G6: AFTER 4 서울랜드(~11/1) | H6: 대소공통 | I6: 주중+주말 | J6: 종일 | K6: 52000 | L6: 17000 | M6: 67 | N6: 67.3 | O6: 1 | P6: 구매일 | Q6: 0 | R6: 날짜지정 | S6: 2026-11-01 | T6: TRUE
A7: 326717 | B7: 4201014 | C7: 테마파크 | D7: 놀이공원 | E7: 과천 | F7: 서울랜드 | G7: AFTER 1 서울랜드(~11/1) | H7: 대소공통 | I7: 주중+주말 | J7: 종일 | K7: 52000 | L7: 19000 | M7: 63 | N7: 63.5 | O7: 1 | P7: 구매일 | Q7: 0 | R7: 날짜지정 | S7: 2026-11-01 | T7: FALSE
A8: 326717 | B8: 4201013 | C8: 테마파크 | D8: 놀이공원 | E8: 과천 | F8: 서울랜드 | G8: 종일권 서울랜드(~11/1) | H8: 대소공통 | I8: 주중+주말 | J8: 종일 | K8: 52000 | L8: 22000 | M8: 58 | N8: 57.7 | O8: 1 | P8: 구매일 | Q8: 0 | R8: 날짜지정 | S8: 2026-11-01 | T8: FALSE
A9: 329117 | B9: 4267023 | C9: 테마파크 | D9: 놀이공원 | E9: 춘천 | F9: 레고랜드 | G9: 주중ㆍ주말 대소공통 레고랜드 2인 종일권(~11/15) | H9: 대소공통 | I9: 주중+주말 | J9: 종일 | K9: 66000 | L9: 36000 | M9: 45 | N9: 45.5 | O9: 2 | P9: 날짜지정 | Q9: 2026-09-22 | R9: 날짜지정 | S9: 2026-11-15 | T9: TRUE
A10: 329117 | B10: 4267024 | C10: 테마파크 | D10: 놀이공원 | E10: 춘천 | F10: 레고랜드 | G10: 주중ㆍ주말 대소공통 레고랜드 3인 종일권(~11/15) | H10: 대소공통 | I10: 주중+주말 | J10: 종일 | K10: 66000 | L10: 36000 | M10: 45 | N10: 45.5 | O10: 3 | P10: 날짜지정 | Q10: 2026-09-22 | R10: 날짜지정 | S10: 2026-11-15 | T10: FALSE
A11: 329117 | B11: 4267025 | C11: 테마파크 | D11: 놀이공원 | E11: 춘천 | F11: 레고랜드 | G11: 주중ㆍ주말 대소공통 레고랜드 4인 종일권(~11/15) | H11: 대소공통 | I11: 주중+주말 | J11: 종일 | K11: 66000 | L11: 36000 | M11: 45 | N11: 45.5 | O11: 4 | P11: 날짜지정 | Q11: 2026-09-22 | R11: 날짜지정 | S11: 2026-11-15 | T11: FALSE
A12: 330505 | B12: 4307271 | C12: 테마파크 | D12: 놀이공원 | E12: 경주 | F12: 경주월드 | G12: 대인 종일권 경주월드(~26/12/31) | H12: 대인 | I12: 주중+주말 | J12: 종일 | K12: 52000 | L12: 34000 | M12: 35 | N12: 34.6 | O12: 1 | P12: 구매일 | Q12: 0 | R12: 날짜지정 | S12: 2026-12-31 | T12: TRUE
A13: 330505 | B13: 4307272 | C13: 테마파크 | D13: 놀이공원 | E13: 경주 | F13: 경주월드 | G13: 소인 종일권 경주월드(~26/12/31) | H13: 소인 | I13: 주중+주말 | J13: 종일 | K13: 39000 | L13: 26500 | M13: 32 | N13: 32.1 | O13: 1 | P13: 구매일 | Q13: 0 | R13: 날짜지정 | S13: 2026-12-31 | T13: FALSE
A14: 328545 | B14: 4258169 | C14: 공연 | D14: 연극 | E14: 서울 | F14: 연극 마트로시카 | G14: 대소공통 관람권 마트로시카 | H14: 대소공통 | I14: 주중+주말 | J14: 종일 | K14: 66000 | L14: 36960 | M14: 44 | N14: 44 | O14: 1 | P14: 구매일 | Q14: 0 | R14: 구매일 | S14: 30 | T14: TRUE
A15: 328609 | B15: 4259802 | C15: 숙박 | D15: 숙박 | E15: 강화 | F15: 엘리야리조트&풀빌라 숙박권 | G15: 디럭스 본관 주중 숙박권 엘리야리조트(~12/30) | I15: 주중 | J15: 종일 | K15: 356800 | L15: 178400 | M15: 50 | N15: 50 | O15: 1 | P15: 날짜지정 | Q15: 2026-09-10 | R15: 날짜지정 | S15: 2026-12-30 | T15: TRUE
A16: 328609 | B16: 4259803 | C16: 숙박 | D16: 숙박 | E16: 강화 | F16: 엘리야리조트&풀빌라 숙박권 | G16: 디럭스 본관 준주말 숙박권 엘리야리조트(~12/30) | I16: 금요일 | J16: 종일 | K16: 472000 | L16: 236000 | M16: 50 | N16: 50 | O16: 1 | P16: 날짜지정 | Q16: 2026-09-10 | R16: 날짜지정 | S16: 2026-12-30 | T16: FALSE
A17: 328609 | B17: 4259808 | C17: 숙박 | D17: 숙박 | E17: 강화 | F17: 엘리야리조트&풀빌라 숙박권 | G17: 디럭스 별관동 주중 숙박권 엘리야리조트(~12/30) | I17: 주중 | J17: 종일 | K17: 504000 | L17: 252000 | M17: 50 | N17: 50 | O17: 1 | P17: 날짜지정 | Q17: 2026-09-10 | R17: 날짜지정 | S17: 2026-12-30 | T17: FALSE
A18: 328609 | B18: 4259805 | C18: 숙박 | D18: 숙박 | E18: 강화 | F18: 엘리야리조트&풀빌라 숙박권 | G18: 스위트 본관 주중 숙박권 엘리야리조트(~12/30) | I18: 주중 | J18: 종일 | K18: 520000 | L18: 260000 | M18: 50 | N18: 50 | O18: 1 | P18: 날짜지정 | Q18: 2026-09-10 | R18: 날짜지정 | S18: 2026-12-30 | T18: FALSE
A19: 328609 | B19: 4259804 | C19: 숙박 | D19: 숙박 | E19: 강화 | F19: 엘리야리조트&풀빌라 숙박권 | G19: 디럭스 본관 주말 숙박권 엘리야리조트(~12/30) | I19: 주말 | J19: 종일 | K19: 552000 | L19: 276000 | M19: 50 | N19: 50 | O19: 1 | P19: 날짜지정 | Q19: 2026-09-10 | R19: 날짜지정 | S19: 2026-12-30 | T19: FALSE
A20: 328609 | B20: 4259809 | C20: 숙박 | D20: 숙박 | E20: 강화 | F20: 엘리야리조트&풀빌라 숙박권 | G20: 디럭스 별관동 준주말 숙박권 엘리야리조트(~12/30) | I20: 금요일 | J20: 종일 | K20: 568000 | L20: 284000 | M20: 50 | N20: 50 | O20: 1 | P20: 날짜지정 | Q20: 2026-09-10 | R20: 날짜지정 | S20: 2026-12-30 | T20: FALSE
A21: 328609 | B21: 4259811 | C21: 숙박 | D21: 숙박 | E21: 강화 | F21: 엘리야리조트&풀빌라 숙박권 | G21: 스위트 별관동 주중 숙박권 엘리야리조트(~12/30) | I21: 주중 | J21: 종일 | K21: 584000 | L21: 292000 | M21: 50 | N21: 50 | O21: 1 | P21: 날짜지정 | Q21: 2026-09-10 | R21: 날짜지정 | S21: 2026-12-30 | T21: FALSE
A22: 328609 | B22: 4259806 | C22: 숙박 | D22: 숙박 | E22: 강화 | F22: 엘리야리조트&풀빌라 숙박권 | G22: 스위트 본관 준주말 숙박권 엘리야리조트(~12/30) | I22: 금요일 | J22: 종일 | K22: 600000 | L22: 300000 | M22: 50 | N22: 50 | O22: 1 | P22: 날짜지정 | Q22: 2026-09-10 | R22: 날짜지정 | S22: 2026-12-30 | T22: FALSE
A23: 328609 | B23: 4259810 | C23: 숙박 | D23: 숙박 | E23: 강화 | F23: 엘리야리조트&풀빌라 숙박권 | G23: 디럭스 별관동 주말 숙박권 엘리야리조트(~12/30) | I23: 주말 | J23: 종일 | K23: 648000 | L23: 324000 | M23: 50 | N23: 50 | O23: 1 | P23: 날짜지정 | Q23: 2026-09-10 | R23: 날짜지정 | S23: 2026-12-30 | T23: FALSE
A24: 328609 | B24: 4259807 | C24: 숙박 | D24: 숙박 | E24: 강화 | F24: 엘리야리조트&풀빌라 숙박권 | G24: 스위트 본관 주말 숙박권 엘리야리조트(~12/30) | I24: 주말 | J24: 종일 | K24: 680000 | L24: 340000 | M24: 50 | N24: 50 | O24: 1 | P24: 날짜지정 | Q24: 2026-09-10 | R24: 날짜지정 | S24: 2026-12-30 | T24: FALSE
A25: 328609 | B25: 4259812 | C25: 숙박 | D25: 숙박 | E25: 강화 | F25: 엘리야리조트&풀빌라 숙박권 | G25: 스위트 별관동 준주말 숙박권 엘리야리조트(~12/30) | I25: 금요일 | J25: 종일 | K25: 680000 | L25: 340000 | M25: 50 | N25: 50 | O25: 1 | P25: 날짜지정 | Q25: 2026-09-10 | R25: 날짜지정 | S25: 2026-12-30 | T25: FALSE
A26: 328609 | B26: 4259813 | C26: 숙박 | D26: 숙박 | E26: 강화 | F26: 엘리야리조트&풀빌라 숙박권 | G26: 스위트 별관동 주말 숙박권 엘리야리조트(~12/30) | I26: 주말 | J26: 종일 | K26: 776000 | L26: 388000 | M26: 50 | N26: 50 | O26: 1 | P26: 날짜지정 | Q26: 2026-09-10 | R26: 날짜지정 | S26: 2026-12-30 | T26: FALSE
... A46: 328673 | B46: 4261754 | C46: 숙박 | D46: 숙박 | E46: 강원 | F46: 에머슨 스위트 낙산 | G46: 에머슨 프리미엄 오션 스위트 공휴일 | I46: 주중+주말 | J46: 종일 | K46: 726000 | L46: 363000 | M46: 50 | N46: 50 | O46: 1 | P46: 날짜지정 | Q46: 2026-09-10 | R46: 날짜지정 | S46: 2026-12-29 | T46: FALSE
A47: 329434 | B47: 4272485 | C47: 워터파크 | D47: 워터파크 | E47: 의정부 | F47: 장암 아일랜드캐슬 워터파크 1인 종일권 | G47: (대소공통)장암 1인 종일권 (9/4~10/31)*구명조끼 미포함 | H47: 대소공통 | I47: 주중+주말 | J47: 종일 | K47: 45000 | L47: 21000 | M47: 53 | N47: 53.3 | O47: 1 | P47: 날짜지정 | Q47: 2026-09-04 | R47: 날짜지정 | S47: 2026-10-31 | T47: TRUE
A48: 225306 | B48: 1795188 | C48: 서울베스트의료의원 | D48: 건강검진 | E48: 서울 | F48: 서울베스트의료의원 건강검진 | G48: 종합건강검진 A형 | K48: 0 | L48: 250000 | M48: 0 | O48: 1 | P48: 구매일 | Q48: 0 | R48: 구매일 | S48: 0 | T48: TRUE
A49: 225306 | B49: 1795189 | C49: 서울베스트의료의원 | D49: 건강검진 | E49: 서울 | F49: 서울베스트의료의원 건강검진 | G49: 종합건강검진 B형 | K49: 0 | L49: 300000 | M49: 0 | O49: 1 | P49: 구매일 | Q49: 0 | R49: 구매일 | S49: 0 | T49: FALSE
A50: 225306 | B50: 1795190 | C50: 서울베스트의료의원 | D50: 건강검진 | E50: 서울 | F50: 서울베스트의료의원 건강검진 | G50: 종합건강검진 C형 | K50: 0 | L50: 500000 | M50: 0 | O50: 1 | P50: 구매일 | Q50: 0 | R50: 구매일 | S50: 0 | T50: FALSE
A51: 324512 | B51: 4137407 | C51: 레져 | D51: 액티비티 | E51: 영월 | F51: 동강흥국래프팅 | G51: 워터밤 물총 대여 동강흥국래프팅(~9/30) | H51: 대소공통 | I51: 주중+주말 | K51: 15000 | L51: 10000 | M51: 33 | N51: 33.3 | O51: 1 | P51: 구매일 | Q51: 0 | R51: 날짜지정 | S51: 2026-09-30 | T51: TRUE
A52: 324512 | B52: 4137389 | C52: 레져 | D52: 액티비티 | E52: 영월 | F52: 동강흥국래프팅 | G52: 래프팅 1인 이용권 동강흥국래프팅(~9/30) | H52: 대소공통 | I52: 주중+주말 | K52: 45000 | L52: 30000 | M52: 33 | N52: 33.3 | O52: 1 | P52: 날짜지정 | Q52: 2026-06-17 | R52: 날짜지정 | S52: 2026-09-30 | T52: FALSE
A53: 324512 | B53: 4137393 | C53: 레져 | D53: 액티비티 | E53: 영월 | F53: 동강흥국래프팅 | G53: 래프팅+다슬기체험 동강흥국래프팅(~9/30) | H53: 대소공통 | I53: 주중+주말 | K53: 55000 | L53: 35000 | M53: 36 | N53: 36.4 | O53: 1 | P53: 구매일 | Q53: 0 | R53: 날짜지정 | S53: 2026-09-30 | T53: FALSE
A54: 324512 | B54: 4137405 | C54: 레져 | D54: 액티비티 | E54: 영월 | F54: 동강흥국래프팅 | G54: 래프팅+조식or중식 동강흥국래프팅(~9/30) | H54: 대소공통 | I54: 주중+주말 | K54: 51000 | L54: 38000 | M54: 25 | N54: 25.5 | O54: 1 | P54: 구매일 | Q54: 0 | R54: 날짜지정 | S54: 2026-09-30 | T54: FALSE
A55: 324512 | B55: 4137395 | C55: 레져 | D55: 액티비티 | E55: 영월 | F55: 동강흥국래프팅 | G55: 래프팅+닭백숙 동강흥국래프팅(~9/30) | H55: 대소공통 | I55: 주중+주말 | K55: 60000 | L55: 45000 | M55: 25 | N55: 25 | O55: 1 | P55: 구매일 | Q55: 0 | R55: 날짜지정 | S55: 2026-09-30 | T55: FALSE
A56: 324512 | B56: 4137397 | C56: 레져 | D56: 액티비티 | E56: 영월 | F56: 동강흥국래프팅 | G56: 래프팅+닭볶음탕 동강흥국래프팅(~9/30) | H56: 대소공통 | I56: 주중+주말 | K56: 60000 | L56: 45000 | M56: 25 | N56: 25 | O56: 1 | P56: 구매일 | Q56: 0 | R56: 날짜지정 | S56: 2026-09-30 | T56: FALSE
A57: 324512 | B57: 4137401 | C57: 레져 | D57: 액티비티 | E57: 영월 | F57: 동강흥국래프팅 | G57: 래프팅+민물매운탕 동강흥국래프팅(~9/30) | H57: 대소공통 | I57: 주중+주말 | K57: 60000 | L57: 45000 | M57: 25 | N57: 25 | O57: 1 | P57: 구매일 | Q57: 0 | R57: 날짜지정 | S57: 2026-09-30 | T57: FALSE
A58: 324512 | B58: 4137391 | C58: 레져 | D58: 액티비티 | E58: 영월 | F58: 동강흥국래프팅 | G58: 래프팅+ATV 동강흥국래프팅(~9/30) | H58: 대소공통 | I58: 주중+주말 | K58: 85000 | L58: 55000 | M58: 35 | N58: 35.3 | O58: 1 | P58: 구매일 | Q58: 0 | R58: 날짜지정 | S58: 2026-09-30 | T58: FALSE
A59: 324512 | B59: 4137403 | C59: 레져 | D59: 액티비티 | E59: 영월 | F59: 동강흥국래프팅 | G59: 래프팅+서바이벌 동강흥국래프팅(~9/30) | H59: 대소공통 | I59: 주중+주말 | K59: 75000 | L59: 55000 | M59: 27 | N59: 26.7 | O59: 1 | P59: 구매일 | Q59: 0 | R59: 날짜지정 | S59: 2026-09-30 | T59: FALSE
...

Sheet 카테고리요약
A1: 대분류 | B1: 소분류 | C1: 상품 수 | D1: 가격대상 수 | E1: 할인율 평균(%) | F1: 할인율 중간값(%) | G1: 할인율 최소(%) | H1: 할인율 최대(%) | I1: 평균 판매가(원) | J1: 0-9% | K1: 10-19% | L1: 20-29% | M1: 30-39% | N1: 40-49% | O1: 50%+
A2: 공연 | B2: 뮤지컬 | C2: =COUNTIFS(상품목록!$B$2:$B$101,A2,상품목록!$C$2:$C$101,B2) | D2: =COUNTIFS(상품목록!$B$2:$B$101,A2,상품목록!$C$2:$C$101,B2,상품목록!$AC$2:$AC$101,"Y") | E2: =IFERROR(ROUND(AVERAGEIFS(상품목록!$K$2:$K$101,상품목록!$B$2:$B$101,A2,상품목록!$C$2:$C$101,B2,상품목록!$AC$2:$AC$101,"Y"),1),"-") | F2: {=IFERROR(MEDIAN(IF((상품목록!$B$2:$B$101=A2)*(상품목록!$C$2:$C$101=B2)*(상품목록!$AC$2:$AC$101="Y"),상품목록!$K$2:$K$101)),"-")} | G2: =IFERROR(_xlfn.MINIFS(상품목록!$K$2:$K$101,상품목록!$B$2:$B$101,A2,상품목록!$C$2:$C$101,B2,상품목록!$AC$2:$AC$101,"Y"),"-") | H2: =IFERROR(_xlfn.MAXIFS(상품목록!$K$2:$K$101,상품목록!$B$2:$B$101,A2,상품목록!$C$2:$C$101,B2,상품목록!$AC$2:$AC$101,"Y"),"-") | I2: =IFERROR(ROUND(AVERAGEIFS(상품목록!$J$2:$J$101,상품목록!$B$2:$B$101,A2,상품목록!$C$2:$C$101,B2,상품목록!$AC$2:$AC$101,"Y"),0),"-") | J2: =COUNTIFS(상품목록!$B$2:$B$101,A2,상품목록!$C$2:$C$101,B2,상품목록!$AC$2:$AC$101,"Y",상품목록!$K$2:$K$101,">=0",상품목록!$K$2:$K$101,"<=9") | K2: =COUNTIFS(상품목록!$B$2:$B$101,A2,상품목록!$C$2:$C$101,B2,상품목록!$AC$2:$AC$101,"Y",상품목록!$K$2:$K$101,">=10",상품목록!$K$2:$K$101,"<=19") | L2: =COUNTIFS(상품목록!$B$2:$B$101,A2,상품목록!$C$2:$C$101,B2,상품목록!$AC$2:$AC$101,"Y",상품목록!$K$2:$K$101,">=20",상품목록!$K$2:$K$101,"<=29") | M2: =COUNTIFS(상품목록!$B$2:$B$101,A2,상품목록!$C$2:$C$101,B2,상품목록!$AC$2:$AC$101,"Y",상품목록!$K$2:$K$101,">=30",상품목록!$K$2:$K$101,"<=39") | N2: =COUNTIFS(상품목록!$B$2:$B$101,A2,상품목록!$C$2:$C$101,B2,상품목록!$AC$2:$AC$101,"Y",상품목록!$K$2:$K$101,">=40",상품목록!$K$2:$K$101,"<=49") | O2: =COUNTIFS(상품목록!$B$2:$B$101,A2,상품목록!$C$2:$C$101,B2,상품목록!$AC$2:$AC$101,"Y",상품목록!$K$2:$K$101,">=50",상품목록!$K$2:$K$101,"<=1000")
A3: 공연 | B3: 연극 | C3: =COUNTIFS(상품목록!$B$2:$B$101,A3,상품목록!$C$2:$C$101,B3) | D3: =COUNTIFS(상품목록!$B$2:$B$101,A3,상품목록!$C$2:$C$101,B3,상품목록!$AC$2:$AC$101,"Y") | E3: =IFERROR(ROUND(AVERAGEIFS(상품목록!$K$2:$K$101,상품목록!$B$2:$B$101,A3,상품목록!$C$2:$C$101,B3,상품목록!$AC$2:$AC$101,"Y"),1),"-") | F3: {=IFERROR(MEDIAN(IF((상품목록!$B$2:$B$101=A3)*(상품목록!$C$2:$C$101=B3)*(상품목록!$AC$2:$AC$101="Y"),상품목록!$K$2:$K$101)),"-")} | G3: =IFERROR(_xlfn.MINIFS(상품목록!$K$2:$K$101,상품목록!$B$2:$B$101,A3,상품목록!$C$2:$C$101,B3,상품목록!$AC$2:$AC$101,"Y"),"-") | H3: =IFERROR(_xlfn.MAXIFS(상품목록!$K$2:$K$101,상품목록!$B$2:$B$101,A3,상품목록!$C$2:$C$101,B3,상품목록!$AC$2:$AC$101,"Y"),"-") | I3: =IFERROR(ROUND(AVERAGEIFS(상품목록!$J$2:$J$101,상품목록!$B$2:$B$101,A3,상품목록!$C$2:$C$101,B3,상품목록!$AC$2:$AC$101,"Y"),0),"-") | J3: =COUNTIFS(상품목록!$B$2:$B$101,A3,상품목록!$C$2:$C$101,B3,상품목록!$AC$2:$AC$101,"Y",상품목록!$K$2:$K$101,">=0",상품목록!$K$2:$K$101,"<=9") | K3: =COUNTIFS(상품목록!$B$2:$B$101,A3,상품목록!$C$2:$C$101,B3,상품목록!$AC$2:$AC$101,"Y",상품목록!$K$2:$K$101,">=10",상품목록!$K$2:$K$101,"<=19") | L3: =COUNTIFS(상품목록!$B$2:$B$101,A3,상품목록!$C$2:$C$101,B3,상품목록!$AC$2:$AC$101,"Y",상품목록!$K$2:$K$101,">=20",상품목록!$K$2:$K$101,"<=29") | M3: =COUNTIFS(상품목록!$B$2:$B$101,A3,상품목록!$C$2:$C$101,B3,상품목록!$AC$2:$AC$101,"Y",상품목록!$K$2:$K$101,">=30",상품목록!$K$2:$K$101,"<=39") | N3: =COUNTIFS(상품목록!$B$2:$B$101,A3,상품목록!$C$2:$C$101,B3,상품목록!$AC$2:$AC$101,"Y",상품목록!$K$2:$K$101,">=40",상품목록!$K$2:$K$101,"<=49") | O3: =COUNTIFS(상품목록!$B$2:$B$101,A3,상품목록!$C$2:$C$101,B3,상품목록!$AC$2:$AC$101,"Y",상품목록!$K$2:$K$101,">=50",상품목록!$K$2:$K$101,"<=1000")
A4: 공연 | B4: 콘서트 | C4: =COUNTIFS(상품목록!$B$2:$B$101,A4,상품목록!$C$2:$C$101,B4) | D4: =COUNTIFS(상품목록!$B$2:$B$101,A4,상품목록!$C$2:$C$101,B4,상품목록!$AC$2:$AC$101,"Y") | E4: =IFERROR(ROUND(AVERAGEIFS(상품목록!$K$2:$K$101,상품목록!$B$2:$B$101,A4,상품목록!$C$2:$C$101,B4,상품목록!$AC$2:$AC$101,"Y"),1),"-") | F4: {=IFERROR(MEDIAN(IF((상품목록!$B$2:$B$101=A4)*(상품목록!$C$2:$C$101=B4)*(상품목록!$AC$2:$AC$101="Y"),상품목록!$K$2:$K$101)),"-")} | G4: =IFERROR(_xlfn.MINIFS(상품목록!$K$2:$K$101,상품목록!$B$2:$B$101,A4,상품목록!$C$2:$C$101,B4,상품목록!$AC$2:$AC$101,"Y"),"-") | H4: =IFERROR(_xlfn.MAXIFS(상품목록!$K$2:$K$101,상품목록!$B$2:$B$101,A4,상품목록!$C$2:$C$101,B4,상품목록!$AC$2:$AC$101,"Y"),"-") | I4: =IFERROR(ROUND(AVERAGEIFS(상품목록!$J$2:$J$101,상품목록!$B$2:$B$101,A4,상품목록!$C$2:$C$101,B4,상품목록!$AC$2:$AC$101,"Y"),0),"-") | J4: =COUNTIFS(상품목록!$B$2:$B$101,A4,상품목록!$C$2:$C$101,B4,상품목록!$AC$2:$AC$101,"Y",상품목록!$K$2:$K$101,">=0",상품목록!$K$2:$K$101,"<=9") | K4: =COUNTIFS(상품목록!$B$2:$B$101,A4,상품목록!$C$2:$C$101,B4,상품목록!$AC$2:$AC$101,"Y",상품목록!$K$2:$K$101,">=10",상품목록!$K$2:$K$101,"<=19") | L4: =COUNTIFS(상품목록!$B$2:$B$101,A4,상품목록!$C$2:$C$101,B4,상품목록!$AC$2:$AC$101,"Y",상품목록!$K$2:$K$101,">=20",상품목록!$K$2:$K$101,"<=29") | M4: =COUNTIFS(상품목록!$B$2:$B$101,A4,상품목록!$C$2:$C$101,B4,상품목록!$AC$2:$AC$101,"Y",상품목록!$K$2:$K$101,">=30",상품목록!$K$2:$K$101,"<=39") | N4: =COUNTIFS(상품목록!$B$2:$B$101,A4,상품목록!$C$2:$C$101,B4,상품목록!$AC$2:$AC$101,"Y",상품목록!$K$2:$K$101,">=40",상품목록!$K$2:$K$101,"<=49") | O4: =COUNTIFS(상품목록!$B$2:$B$101,A4,상품목록!$C$2:$C$101,B4,상품목록!$AC$2:$AC$101,"Y",상품목록!$K$2:$K$101,">=50",상품목록!$K$2:$K$101,"<=1000")
A5: 레져 | B5: 액티비티 | C5: =COUNTIFS(상품목록!$B$2:$B$101,A5,상품목록!$C$2:$C$101,B5) | D5: =COUNTIFS(상품목록!$B$2:$B$101,A5,상품목록!$C$2:$C$101,B5,상품목록!$AC$2:$AC$101,"Y") | E5: =IFERROR(ROUND(AVERAGEIFS(상품목록!$K$2:$K$101,상품목록!$B$2:$B$101,A5,상품목록!$C$2:$C$101,B5,상품목록!$AC$2:$AC$101,"Y"),1),"-") | F5: {=IFERROR(MEDIAN(IF((상품목록!$B$2:$B$101=A5)*(상품목록!$C$2:$C$101=B5)*(상품목록!$AC$2:$AC$101="Y"),상품목록!$K$2:$K$101)),"-")} | G5: =IFERROR(_xlfn.MINIFS(상품목록!$K$2:$K$101,상품목록!$B$2:$B$101,A5,상품목록!$C$2:$C$101,B5,상품목록!$AC$2:$AC$101,"Y"),"-") | H5: =IFERROR(_xlfn.MAXIFS(상품목록!$K$2:$K$101,상품목록!$B$2:$B$101,A5,상품목록!$C$2:$C$101,B5,상품목록!$AC$2:$AC$101,"Y"),"-") | I5: =IFERROR(ROUND(AVERAGEIFS(상품목록!$J$2:$J$101,상품목록!$B$2:$B$101,A5,상품목록!$C$2:$C$101,B5,상품목록!$AC$2:$AC$101,"Y"),0),"-") | J5: =COUNTIFS(상품목록!$B$2:$B$101,A5,상품목록!$C$2:$C$101,B5,상품목록!$AC$2:$AC$101,"Y",상품목록!$K$2:$K$101,">=0",상품목록!$K$2:$K$101,"<=9") | K5: =COUNTIFS(상품목록!$B$2:$B$101,A5,상품목록!$C$2:$C$101,B5,상품목록!$AC$2:$AC$101,"Y",상품목록!$K$2:$K$101,">=10",상품목록!$K$2:$K$101,"<=19") | L5: =COUNTIFS(상품목록!$B$2:$B$101,A5,상품목록!$C$2:$C$101,B5,상품목록!$AC$2:$AC$101,"Y",상품목록!$K$2:$K$101,">=20",상품목록!$K$2:$K$101,"<=29") | M5: =COUNTIFS(상품목록!$B$2:$B$101,A5,상품목록!$C$2:$C$101,B5,상품목록!$AC$2:$AC$101,"Y",상품목록!$K$2:$K$101,">=30",상품목록!$K$2:$K$101,"<=39") | N5: =COUNTIFS(상품목록!$B$2:$B$101,A5,상품목록!$C$2:$C$101,B5,상품목록!$AC$2:$AC$101,"Y",상품목록!$K$2:$K$101,">=40",상품목록!$K$2:$K$101,"<=49") | O5: =COUNTIFS(상품목록!$B$2:$B$101,A5,상품목록!$C$2:$C$101,B5,상품목록!$AC$2:$AC$101,"Y",상품목록!$K$2:$K$101,">=50",상품목록!$K$2:$K$101,"<=1000")
A6: 레져 | B6: 크루즈 | C6: =COUNTIFS(상품목록!$B$2:$B$101,A6,상품목록!$C$2:$C$101,B6) | D6: =COUNTIFS(상품목록!$B$2:$B$101,A6,상품목록!$C$2:$C$101,B6,상품목록!$AC$2:$AC$101,"Y") | E6: =IFERROR(ROUND(AVERAGEIFS(상품목록!$K$2:$K$101,상품목록!$B$2:$B$101,A6,상품목록!$C$2:$C$101,B6,상품목록!$AC$2:$AC$101,"Y"),1),"-") | F6: {=IFERROR(MEDIAN(IF((상품목록!$B$2:$B$101=A6)*(상품목록!$C$2:$C$101=B6)*(상품목록!$AC$2:$AC$101="Y"),상품목록!$K$2:$K$101)),"-")} | G6: =IFERROR(_xlfn.MINIFS(상품목록!$K$2:$K$101,상품목록!$B$2:$B$101,A6,상품목록!$C$2:$C$101,B6,상품목록!$AC$2:$AC$101,"Y"),"-") | H6: =IFERROR(_xlfn.MAXIFS(상품목록!$K$2:$K$101,상품목록!$B$2:$B$101,A6,상품목록!$C$2:$C$101,B6,상품목록!$AC$2:$AC$101,"Y"),"-") | I6: =IFERROR(ROUND(AVERAGEIFS(상품목록!$J$2:$J$101,상품목록!$B$2:$B$101,A6,상품목록!$C$2:$C$101,B6,상품목록!$AC$2:$AC$101,"Y"),0),"-") | J6: =COUNTIFS(상품목록!$B$2:$B$101,A6,상품목록!$C$2:$C$101,B6,상품목록!$AC$2:$AC$101,"Y",상품목록!$K$2:$K$101,">=0",상품목록!$K$2:$K$101,"<=9") | K6: =COUNTIFS(상품목록!$B$2:$B$101,A6,상품목록!$C$2:$C$101,B6,상품목록!$AC$2:$AC$101,"Y",상품목록!$K$2:$K$101,">=10",상품목록!$K$2:$K$101,"<=19") | L6: =COUNTIFS(상품목록!$B$2:$B$101,A6,상품목록!$C$2:$C$101,B6,상품목록!$AC$2:$AC$101,"Y",상품목록!$K$2:$K$101,">=20",상품목록!$K$2:$K$101,"<=29") | M6: =COUNTIFS(상품목록!$B$2:$B$101,A6,상품목록!$C$2:$C$101,B6,상품목록!$AC$2:$AC$101,"Y",상품목록!$K$2:$K$101,">=30",상품목록!$K$2:$K$101,"<=39") | N6: =COUNTIFS(상품목록!$B$2:$B$101,A6,상품목록!$C$2:$C$101,B6,상품목록!$AC$2:$AC$101,"Y",상품목록!$K$2:$K$101,">=40",상품목록!$K$2:$K$101,"<=49") | O6: =COUNTIFS(상품목록!$B$2:$B$101,A6,상품목록!$C$2:$C$101,B6,상품목록!$AC$2:$AC$101,"Y",상품목록!$K$2:$K$101,">=50",상품목록!$K$2:$K$101,"<=1000")
A7: 삼성미라클안과 | B7: 라식·라섹 | C7: =COUNTIFS(상품목록!$B$2:$B$101,A7,상품목록!$C$2:$C$101,B7) | D7: =COUNTIFS(상품목록!$B$2:$B$101,A7,상품목록!$C$2:$C$101,B7,상품목록!$AC$2:$AC$101,"Y") | E7: =IFERROR(ROUND(AVERAGEIFS(상품목록!$K$2:$K$101,상품목록!$B$2:$B$101,A7,상품목록!$C$2:$C$101,B7,상품목록!$AC$2:$AC$101,"Y"),1),"-") | F7: {=IFERROR(MEDIAN(IF((상품목록!$B$2:$B$101=A7)*(상품목록!$C$2:$C$101=B7)*(상품목록!$AC$2:$AC$101="Y"),상품목록!$K$2:$K$101)),"-")} | G7: =IFERROR(_xlfn.MINIFS(상품목록!$K$2:$K$101,상품목록!$B$2:$B$101,A7,상품목록!$C$2:$C$101,B7,상품목록!$AC$2:$AC$101,"Y"),"-") | H7: =IFERROR(_xlfn.MAXIFS(상품목록!$K$2:$K$101,상품목록!$B$2:$B$101,A7,상품목록!$C$2:$C$101,B7,상품목록!$AC$2:$AC$101,"Y"),"-") | I7: =IFERROR(ROUND(AVERAGEIFS(상품목록!$J$2:$J$101,상품목록!$B$2:$B$101,A7,상품목록!$C$2:$C$101,B7,상품목록!$AC$2:$AC$101,"Y"),0),"-") | J7: =COUNTIFS(상품목록!$B$2:$B$101,A7,상품목록!$C$2:$C$101,B7,상품목록!$AC$2:$AC$101,"Y",상품목록!$K$2:$K$101,">=0",상품목록!$K$2:$K$101,"<=9") | K7: =COUNTIFS(상품목록!$B$2:$B$101,A7,상품목록!$C$2:$C$101,B7,상품목록!$AC$2:$AC$101,"Y",상품목록!$K$2:$K$101,">=10",상품목록!$K$2:$K$101,"<=19") | L7: =COUNTIFS(상품목록!$B$2:$B$101,A7,상품목록!$C$2:$C$101,B7,상품목록!$AC$2:$AC$101,"Y",상품목록!$K$2:$K$101,">=20",상품목록!$K$2:$K$101,"<=29") | M7: =COUNTIFS(상품목록!$B$2:$B$101,A7,상품목록!$C$2:$C$101,B7,상품목록!$AC$2:$AC$101,"Y",상품목록!$K$2:$K$101,">=30",상품목록!$K$2:$K$101,"<=39") | N7: =COUNTIFS(상품목록!$B$2:$B$101,A7,상품목록!$C$2:$C$101,B7,상품목록!$AC$2:$AC$101,"Y",상품목록!$K$2:$K$101,">=40",상품목록!$K$2:$K$101,"<=49") | O7: =COUNTIFS(상품목록!$B$2:$B$101,A7,상품목록!$C$2:$C$101,B7,상품목록!$AC$2:$AC$101,"Y",상품목록!$K$2:$K$101,">=50",상품목록!$K$2:$K$101,"<=1000")
A8: 서울베스트의료의원 | B8: 건강검진 | C8: =COUNTIFS(상품목록!$B$2:$B$101,A8,상품목록!$C$2:$C$101,B8) | D8: =COUNTIFS(상품목록!$B$2:$B$101,A8,상품목록!$C$2:$C$101,B8,상품목록!$AC$2:$AC$101,"Y") | E8: =IFERROR(ROUND(AVERAGEIFS(상품목록!$K$2:$K$101,상품목록!$B$2:$B$101,A8,상품목록!$C$2:$C$101,B8,상품목록!$AC$2:$AC$101,"Y"),1),"-") | F8: {=IFERROR(MEDIAN(IF((상품목록!$B$2:$B$101=A8)*(상품목록!$C$2:$C$101=B8)*(상품목록!$AC$2:$AC$101="Y"),상품목록!$K$2:$K$101)),"-")} | G8: =IFERROR(_xlfn.MINIFS(상품목록!$K$2:$K$101,상품목록!$B$2:$B$101,A8,상품목록!$C$2:$C$101,B8,상품목록!$AC$2:$AC$101,"Y"),"-") | H8: =IFERROR(_xlfn.MAXIFS(상품목록!$K$2:$K$101,상품목록!$B$2:$B$101,A8,상품목록!$C$2:$C$101,B8,상품목록!$AC$2:$AC$101,"Y"),"-") | I8: =IFERROR(ROUND(AVERAGEIFS(상품목록!$J$2:$J$101,상품목록!$B$2:$B$101,A8,상품목록!$C$2:$C$101,B8,상품목록!$AC$2:$AC$101,"Y"),0),"-") | J8: =COUNTIFS(상품목록!$B$2:$B$101,A8,상품목록!$C$2:$C$101,B8,상품목록!$AC$2:$AC$101,"Y",상품목록!$K$2:$K$101,">=0",상품목록!$K$2:$K$101,"<=9") | K8: =COUNTIFS(상품목록!$B$2:$B$101,A8,상품목록!$C$2:$C$101,B8,상품목록!$AC$2:$AC$101,"Y",상품목록!$K$2:$K$101,">=10",상품목록!$K$2:$K$101,"<=19") | L8: =COUNTIFS(상품목록!$B$2:$B$101,A8,상품목록!$C$2:$C$101,B8,상품목록!$AC$2:$AC$101,"Y",상품목록!$K$2:$K$101,">=20",상품목록!$K$2:$K$101,"<=29") | M8: =COUNTIFS(상품목록!$B$2:$B$101,A8,상품목록!$C$2:$C$101,B8,상품목록!$AC$2:$AC$101,"Y",상품목록!$K$2:$K$101,">=30",상품목록!$K$2:$K$101,"<=39") | N8: =COUNTIFS(상품목록!$B$2:$B$101,A8,상품목록!$C$2:$C$101,B8,상품목록!$AC$2:$AC$101,"Y",상품목록!$K$2:$K$101,">=40",상품목록!$K$2:$K$101,"<=49") | O8: =COUNTIFS(상품목록!$B$2:$B$101,A8,상품목록!$C$2:$C$101,B8,상품목록!$AC$2:$AC$101,"Y",상품목록!$K$2:$K$101,">=50",상품목록!$K$2:$K$101,"<=1000")
A9: 숙박 | B9: 숙박 | C9: =COUNTIFS(상품목록!$B$2:$B$101,A9,상품목록!$C$2:$C$101,B9) | D9: =COUNTIFS(상품목록!$B$2:$B$101,A9,상품목록!$C$2:$C$101,B9,상품목록!$AC$2:$AC$101,"Y") | E9: =IFERROR(ROUND(AVERAGEIFS(상품목록!$K$2:$K$101,상품목록!$B$2:$B$101,A9,상품목록!$C$2:$C$101,B9,상품목록!$AC$2:$AC$101,"Y"),1),"-") | F9: {=IFERROR(MEDIAN(IF((상품목록!$B$2:$B$101=A9)*(상품목록!$C$2:$C$101=B9)*(상품목록!$AC$2:$AC$101="Y"),상품목록!$K$2:$K$101)),"-")} | G9: =IFERROR(_xlfn.MINIFS(상품목록!$K$2:$K$101,상품목록!$B$2:$B$101,A9,상품목록!$C$2:$C$101,B9,상품목록!$AC$2:$AC$101,"Y"),"-") | H9: =IFERROR(_xlfn.MAXIFS(상품목록!$K$2:$K$101,상품목록!$B$2:$B$101,A9,상품목록!$C$2:$C$101,B9,상품목록!$AC$2:$AC$101,"Y"),"-") | I9: =IFERROR(ROUND(AVERAGEIFS(상품목록!$J$2:$J$101,상품목록!$B$2:$B$101,A9,상품목록!$C$2:$C$101,B9,상품목록!$AC$2:$AC$101,"Y"),0),"-") | J9: =COUNTIFS(상품목록!$B$2:$B$101,A9,상품목록!$C$2:$C$101,B9,상품목록!$AC$2:$AC$101,"Y",상품목록!$K$2:$K$101,">=0",상품목록!$K$2:$K$101,"<=9") | K9: =COUNTIFS(상품목록!$B$2:$B$101,A9,상품목록!$C$2:$C$101,B9,상품목록!$AC$2:$AC$101,"Y",상품목록!$K$2:$K$101,">=10",상품목록!$K$2:$K$101,"<=19") | L9: =COUNTIFS(상품목록!$B$2:$B$101,A9,상품목록!$C$2:$C$101,B9,상품목록!$AC$2:$AC$101,"Y",상품목록!$K$2:$K$101,">=20",상품목록!$K$2:$K$101,"<=29") | M9: =COUNTIFS(상품목록!$B$2:$B$101,A9,상품목록!$C$2:$C$101,B9,상품목록!$AC$2:$AC$101,"Y",상품목록!$K$2:$K$101,">=30",상품목록!$K$2:$K$101,"<=39") | N9: =COUNTIFS(상품목록!$B$2:$B$101,A9,상품목록!$C$2:$C$101,B9,상품목록!$AC$2:$AC$101,"Y",상품목록!$K$2:$K$101,">=40",상품목록!$K$2:$K$101,"<=49") | O9: =COUNTIFS(상품목록!$B$2:$B$101,A9,상품목록!$C$2:$C$101,B9,상품목록!$AC$2:$AC$101,"Y",상품목록!$K$2:$K$101,">=50",상품목록!$K$2:$K$101,"<=1000")
A10: 워터파크 | B10: 워터파크 | C10: =COUNTIFS(상품목록!$B$2:$B$101,A10,상품목록!$C$2:$C$101,B10) | D10: =COUNTIFS(상품목록!$B$2:$B$101,A10,상품목록!$C$2:$C$101,B10,상품목록!$AC$2:$AC$101,"Y") | E10: =IFERROR(ROUND(AVERAGEIFS(상품목록!$K$2:$K$101,상품목록!$B$2:$B$101,A10,상품목록!$C$2:$C$101,B10,상품목록!$AC$2:$AC$101,"Y"),1),"-") | F10: {=IFERROR(MEDIAN(IF((상품목록!$B$2:$B$101=A10)*(상품목록!$C$2:$C$101=B10)*(상품목록!$AC$2:$AC$101="Y"),상품목록!$K$2:$K$101)),"-")} | G10: =IFERROR(_xlfn.MINIFS(상품목록!$K$2:$K$101,상품목록!$B$2:$B$101,A10,상품목록!$C$2:$C$101,B10,상품목록!$AC$2:$AC$101,"Y"),"-") | H10: =IFERROR(_xlfn.MAXIFS(상품목록!$K$2:$K$101,상품목록!$B$2:$B$101,A10,상품목록!$C$2:$C$101,B10,상품목록!$AC$2:$AC$101,"Y"),"-") | I10: =IFERROR(ROUND(AVERAGEIFS(상품목록!$J$2:$J$101,상품목록!$B$2:$B$101,A10,상품목록!$C$2:$C$101,B10,상품목록!$AC$2:$AC$101,"Y"),0),"-") | J10: =COUNTIFS(상품목록!$B$2:$B$101,A10,상품목록!$C$2:$C$101,B10,상품목록!$AC$2:$AC$101,"Y",상품목록!$K$2:$K$101,">=0",상품목록!$K$2:$K$101,"<=9") | K10: =COUNTIFS(상품목록!$B$2:$B$101,A10,상품목록!$C$2:$C$101,B10,상품목록!$AC$2:$AC$101,"Y",상품목록!$K$2:$K$101,">=10",상품목록!$K$2:$K$101,"<=19") | L10: =COUNTIFS(상품목록!$B$2:$B$101,A10,상품목록!$C$2:$C$101,B10,상품목록!$AC$2:$AC$101,"Y",상품목록!$K$2:$K$101,">=20",상품목록!$K$2:$K$101,"<=29") | M10: =COUNTIFS(상품목록!$B$2:$B$101,A10,상품목록!$C$2:$C$101,B10,상품목록!$AC$2:$AC$101,"Y",상품목록!$K$2:$K$101,">=30",상품목록!$K$2:$K$101,"<=39") | N10: =COUNTIFS(상품목록!$B$2:$B$101,A10,상품목록!$C$2:$C$101,B10,상품목록!$AC$2:$AC$101,"Y",상품목록!$K$2:$K$101,">=40",상품목록!$K$2:$K$101,"<=49") | O10: =COUNTIFS(상품목록!$B$2:$B$101,A10,상품목록!$C$2:$C$101,B10,상품목록!$AC$2:$AC$101,"Y",상품목록!$K$2:$K$101,">=50",상품목록!$K$2:$K$101,"<=1000")
A11: 자동차 구매 | B11: 제네시스 | C11: =COUNTIFS(상품목록!$B$2:$B$101,A11,상품목록!$C$2:$C$101,B11) | D11: =COUNTIFS(상품목록!$B$2:$B$101,A11,상품목록!$C$2:$C$101,B11,상품목록!$AC$2:$AC$101,"Y") | E11: =IFERROR(ROUND(AVERAGEIFS(상품목록!$K$2:$K$101,상품목록!$B$2:$B$101,A11,상품목록!$C$2:$C$101,B11,상품목록!$AC$2:$AC$101,"Y"),1),"-") | F11: {=IFERROR(MEDIAN(IF((상품목록!$B$2:$B$101=A11)*(상품목록!$C$2:$C$101=B11)*(상품목록!$AC$2:$AC$101="Y"),상품목록!$K$2:$K$101)),"-")} | G11: =IFERROR(_xlfn.MINIFS(상품목록!$K$2:$K$101,상품목록!$B$2:$B$101,A11,상품목록!$C$2:$C$101,B11,상품목록!$AC$2:$AC$101,"Y"),"-") | H11: =IFERROR(_xlfn.MAXIFS(상품목록!$K$2:$K$101,상품목록!$B$2:$B$101,A11,상품목록!$C$2:$C$101,B11,상품목록!$AC$2:$AC$101,"Y"),"-") | I11: =IFERROR(ROUND(AVERAGEIFS(상품목록!$J$2:$J$101,상품목록!$B$2:$B$101,A11,상품목록!$C$2:$C$101,B11,상품목록!$AC$2:$AC$101,"Y"),0),"-") | J11: =COUNTIFS(상품목록!$B$2:$B$101,A11,상품목록!$C$2:$C$101,B11,상품목록!$AC$2:$AC$101,"Y",상품목록!$K$2:$K$101,">=0",상품목록!$K$2:$K$101,"<=9") | K11: =COUNTIFS(상품목록!$B$2:$B$101,A11,상품목록!$C$2:$C$101,B11,상품목록!$AC$2:$AC$101,"Y",상품목록!$K$2:$K$101,">=10",상품목록!$K$2:$K$101,"<=19") | L11: =COUNTIFS(상품목록!$B$2:$B$101,A11,상품목록!$C$2:$C$101,B11,상품목록!$AC$2:$AC$101,"Y",상품목록!$K$2:$K$101,">=20",상품목록!$K$2:$K$101,"<=29") | M11: =COUNTIFS(상품목록!$B$2:$B$101,A11,상품목록!$C$2:$C$101,B11,상품목록!$AC$2:$AC$101,"Y",상품목록!$K$2:$K$101,">=30",상품목록!$K$2:$K$101,"<=39") | N11: =COUNTIFS(상품목록!$B$2:$B$101,A11,상품목록!$C$2:$C$101,B11,상품목록!$AC$2:$AC$101,"Y",상품목록!$K$2:$K$101,">=40",상품목록!$K$2:$K$101,"<=49") | O11: =COUNTIFS(상품목록!$B$2:$B$101,A11,상품목록!$C$2:$C$101,B11,상품목록!$AC$2:$AC$101,"Y",상품목록!$K$2:$K$101,">=50",상품목록!$K$2:$K$101,"<=1000")
A12: 전시 | B12: 박물관 | C12: =COUNTIFS(상품목록!$B$2:$B$101,A12,상품목록!$C$2:$C$101,B12) | D12: =COUNTIFS(상품목록!$B$2:$B$101,A12,상품목록!$C$2:$C$101,B12,상품목록!$AC$2:$AC$101,"Y") | E12: =IFERROR(ROUND(AVERAGEIFS(상품목록!$K$2:$K$101,상품목록!$B$2:$B$101,A12,상품목록!$C$2:$C$101,B12,상품목록!$AC$2:$AC$101,"Y"),1),"-") | F12: {=IFERROR(MEDIAN(IF((상품목록!$B$2:$B$101=A12)*(상품목록!$C$2:$C$101=B12)*(상품목록!$AC$2:$AC$101="Y"),상품목록!$K$2:$K$101)),"-")} | G12: =IFERROR(_xlfn.MINIFS(상품목록!$K$2:$K$101,상품목록!$B$2:$B$101,A12,상품목록!$C$2:$C$101,B12,상품목록!$AC$2:$AC$101,"Y"),"-") | H12: =IFERROR(_xlfn.MAXIFS(상품목록!$K$2:$K$101,상품목록!$B$2:$B$101,A12,상품목록!$C$2:$C$101,B12,상품목록!$AC$2:$AC$101,"Y"),"-") | I12: =IFERROR(ROUND(AVERAGEIFS(상품목록!$J$2:$J$101,상품목록!$B$2:$B$101,A12,상품목록!$C$2:$C$101,B12,상품목록!$AC$2:$AC$101,"Y"),0),"-") | J12: =COUNTIFS(상품목록!$B$2:$B$101,A12,상품목록!$C$2:$C$101,B12,상품목록!$AC$2:$AC$101,"Y",상품목록!$K$2:$K$101,">=0",상품목록!$K$2:$K$101,"<=9") | K12: =COUNTIFS(상품목록!$B$2:$B$101,A12,상품목록!$C$2:$C$101,B12,상품목록!$AC$2:$AC$101,"Y",상품목록!$K$2:$K$101,">=10",상품목록!$K$2:$K$101,"<=19") | L12: =COUNTIFS(상품목록!$B$2:$B$101,A12,상품목록!$C$2:$C$101,B12,상품목록!$AC$2:$AC$101,"Y",상품목록!$K$2:$K$101,">=20",상품목록!$K$2:$K$101,"<=29") | M12: =COUNTIFS(상품목록!$B$2:$B$101,A12,상품목록!$C$2:$C$101,B12,상품목록!$AC$2:$AC$101,"Y",상품목록!$K$2:$K$101,">=30",상품목록!$K$2:$K$101,"<=39") | N12: =COUNTIFS(상품목록!$B$2:$B$101,A12,상품목록!$C$2:$C$101,B12,상품목록!$AC$2:$AC$101,"Y",상품목록!$K$2:$K$101,">=40",상품목록!$K$2:$K$101,"<=49") | O12: =COUNTIFS(상품목록!$B$2:$B$101,A12,상품목록!$C$2:$C$101,B12,상품목록!$AC$2:$AC$101,"Y",상품목록!$K$2:$K$101,">=50",상품목록!$K$2:$K$101,"<=1000")
A13: 테마파크 | B13: 놀이공원 | C13: =COUNTIFS(상품목록!$B$2:$B$101,A13,상품목록!$C$2:$C$101,B13) | D13: =COUNTIFS(상품목록!$B$2:$B$101,A13,상품목록!$C$2:$C$101,B13,상품목록!$AC$2:$AC$101,"Y") | E13: =IFERROR(ROUND(AVERAGEIFS(상품목록!$K$2:$K$101,상품목록!$B$2:$B$101,A13,상품목록!$C$2:$C$101,B13,상품목록!$AC$2:$AC$101,"Y"),1),"-") | F13: {=IFERROR(MEDIAN(IF((상품목록!$B$2:$B$101=A13)*(상품목록!$C$2:$C$101=B13)*(상품목록!$AC$2:$AC$101="Y"),상품목록!$K$2:$K$101)),"-")} | G13: =IFERROR(_xlfn.MINIFS(상품목록!$K$2:$K$101,상품목록!$B$2:$B$101,A13,상품목록!$C$2:$C$101,B13,상품목록!$AC$2:$AC$101,"Y"),"-") | H13: =IFERROR(_xlfn.MAXIFS(상품목록!$K$2:$K$101,상품목록!$B$2:$B$101,A13,상품목록!$C$2:$C$101,B13,상품목록!$AC$2:$AC$101,"Y"),"-") | I13: =IFERROR(ROUND(AVERAGEIFS(상품목록!$J$2:$J$101,상품목록!$B$2:$B$101,A13,상품목록!$C$2:$C$101,B13,상품목록!$AC$2:$AC$101,"Y"),0),"-") | J13: =COUNTIFS(상품목록!$B$2:$B$101,A13,상품목록!$C$2:$C$101,B13,상품목록!$AC$2:$AC$101,"Y",상품목록!$K$2:$K$101,">=0",상품목록!$K$2:$K$101,"<=9") | K13: =COUNTIFS(상품목록!$B$2:$B$101,A13,상품목록!$C$2:$C$101,B13,상품목록!$AC$2:$AC$101,"Y",상품목록!$K$2:$K$101,">=10",상품목록!$K$2:$K$101,"<=19") | L13: =COUNTIFS(상품목록!$B$2:$B$101,A13,상품목록!$C$2:$C$101,B13,상품목록!$AC$2:$AC$101,"Y",상품목록!$K$2:$K$101,">=20",상품목록!$K$2:$K$101,"<=29") | M13: =COUNTIFS(상품목록!$B$2:$B$101,A13,상품목록!$C$2:$C$101,B13,상품목록!$AC$2:$AC$101,"Y",상품목록!$K$2:$K$101,">=30",상품목록!$K$2:$K$101,"<=39") | N13: =COUNTIFS(상품목록!$B$2:$B$101,A13,상품목록!$C$2:$C$101,B13,상품목록!$AC$2:$AC$101,"Y",상품목록!$K$2:$K$101,">=40",상품목록!$K$2:$K$101,"<=49") | O13: =COUNTIFS(상품목록!$B$2:$B$101,A13,상품목록!$C$2:$C$101,B13,상품목록!$AC$2:$AC$101,"Y",상품목록!$K$2:$K$101,">=50",상품목록!$K$2:$K$101,"<=1000")
... A16: 헬스&푸드 | B16: 푸드 | C16: =COUNTIFS(상품목록!$B$2:$B$101,A16,상품목록!$C$2:$C$101,B16) | D16: =COUNTIFS(상품목록!$B$2:$B$101,A16,상품목록!$C$2:$C$101,B16,상품목록!$AC$2:$AC$101,"Y") | E16: =IFERROR(ROUND(AVERAGEIFS(상품목록!$K$2:$K$101,상품목록!$B$2:$B$101,A16,상품목록!$C$2:$C$101,B16,상품목록!$AC$2:$AC$101,"Y"),1),"-") | F16: {=IFERROR(MEDIAN(IF((상품목록!$B$2:$B$101=A16)*(상품목록!$C$2:$C$101=B16)*(상품목록!$AC$2:$AC$101="Y"),상품목록!$K$2:$K$101)),"-")} | G16: =IFERROR(_xlfn.MINIFS(상품목록!$K$2:$K$101,상품목록!$B$2:$B$101,A16,상품목록!$C$2:$C$101,B16,상품목록!$AC$2:$AC$101,"Y"),"-") | H16: =IFERROR(_xlfn.MAXIFS(상품목록!$K$2:$K$101,상품목록!$B$2:$B$101,A16,상품목록!$C$2:$C$101,B16,상품목록!$AC$2:$AC$101,"Y"),"-") | I16: =IFERROR(ROUND(AVERAGEIFS(상품목록!$J$2:$J$101,상품목록!$B$2:$B$101,A16,상품목록!$C$2:$C$101,B16,상품목록!$AC$2:$AC$101,"Y"),0),"-") | J16: =COUNTIFS(상품목록!$B$2:$B$101,A16,상품목록!$C$2:$C$101,B16,상품목록!$AC$2:$AC$101,"Y",상품목록!$K$2:$K$101,">=0",상품목록!$K$2:$K$101,"<=9") | K16: =COUNTIFS(상품목록!$B$2:$B$101,A16,상품목록!$C$2:$C$101,B16,상품목록!$AC$2:$AC$101,"Y",상품목록!$K$2:$K$101,">=10",상품목록!$K$2:$K$101,"<=19") | L16: =COUNTIFS(상품목록!$B$2:$B$101,A16,상품목록!$C$2:$C$101,B16,상품목록!$AC$2:$AC$101,"Y",상품목록!$K$2:$K$101,">=20",상품목록!$K$2:$K$101,"<=29") | M16: =COUNTIFS(상품목록!$B$2:$B$101,A16,상품목록!$C$2:$C$101,B16,상품목록!$AC$2:$AC$101,"Y",상품목록!$K$2:$K$101,">=30",상품목록!$K$2:$K$101,"<=39") | N16: =COUNTIFS(상품목록!$B$2:$B$101,A16,상품목록!$C$2:$C$101,B16,상품목록!$AC$2:$AC$101,"Y",상품목록!$K$2:$K$101,">=40",상품목록!$K$2:$K$101,"<=49") | O16: =COUNTIFS(상품목록!$B$2:$B$101,A16,상품목록!$C$2:$C$101,B16,상품목록!$AC$2:$AC$101,"Y",상품목록!$K$2:$K$101,">=50",상품목록!$K$2:$K$101,"<=1000")
A17: 전체 | C17: =COUNTA(상품목록!$A$2:$A$101) | D17: =COUNTIF(상품목록!$AC$2:$AC$101,"Y") | E17: =ROUND(AVERAGEIF(상품목록!$AC$2:$AC$101,"Y",상품목록!$K$2:$K$101),1) | F17: {=MEDIAN(IF(상품목록!$AC$2:$AC$101="Y",상품목록!$K$2:$K$101))} | G17: =_xlfn.MINIFS(상품목록!$K$2:$K$101,상품목록!$AC$2:$AC$101,"Y") | H17: =_xlfn.MAXIFS(상품목록!$K$2:$K$101,상품목록!$AC$2:$AC$101,"Y") | I17: =ROUND(AVERAGEIF(상품목록!$AC$2:$AC$101,"Y",상품목록!$J$2:$J$101),0) | J17: =COUNTIFS(상품목록!$AC$2:$AC$101,"Y",상품목록!$K$2:$K$101,">=0",상품목록!$K$2:$K$101,"<=9") | K17: =COUNTIFS(상품목록!$AC$2:$AC$101,"Y",상품목록!$K$2:$K$101,">=10",상품목록!$K$2:$K$101,"<=19") | L17: =COUNTIFS(상품목록!$AC$2:$AC$101,"Y",상품목록!$K$2:$K$101,">=20",상품목록!$K$2:$K$101,"<=29") | M17: =COUNTIFS(상품목록!$AC$2:$AC$101,"Y",상품목록!$K$2:$K$101,">=30",상품목록!$K$2:$K$101,"<=39") | N17: =COUNTIFS(상품목록!$AC$2:$AC$101,"Y",상품목록!$K$2:$K$101,">=40",상품목록!$K$2:$K$101,"<=49") | O17: =COUNTIFS(상품목록!$AC$2:$AC$101,"Y",상품목록!$K$2:$K$101,">=50",상품목록!$K$2:$K$101,"<=1000")
A19: 가격대상 = 광고상품·가격 없음 제외 (상품목록 priced=Y). 할인율은 사이트 표기값.
A20: 대분류·소분류는 상품목록 cat1·cat2 일치로 셈 (수집 시점 복수 카테고리 상품 없음). 중간값 열은 배열수식.

Sheet 전북·충남
A1: 시도 | B1: product_id | C1: cat2 | D1: region | E1: name | F1: list_price | G1: sale_price | H1: discount_pct | I1: basis | J1: issue_type | K1: issue_channel | L1: vendor_name | M1: vendor_address
A2: 서울;충남 | B2: 243478 | C2: 라식·라섹 | D2: 서울/천안 | E2: 삼성미라클안과 라식·라섹 | F2: 1600000 | G2: 890000 | H2: 44 | I2: 미라클라섹 | J2: 광고상품 | L2: 삼성미라클안과
A3: 충남 | B3: 330442 | C3: 워터파크 | D3: 아산 | E3: 아산스파비스 | F3: 50000 | G3: 20000 | H3: 60 | I3: 주중·주말공통이용권 아산스파비스(~26/12/31) | J3: 즉시발송 | K3: LMS 문자 | L3: 아산스파비스 | M3: 충남 아산시 음봉면 아산온천로157번길 67 아산스파비스
A4: 충남 | B4: 326087 | C4: 워터파크 | D4: 예산 | E4: 스플라스 리솜 워터파크 | F4: 40000 | G4: 27400 | H4: 32 | I4: 소인입장권 스플라스 워터파크(8/24~10/31) | J4: 즉시발송 | K4: 플레이스토리 | L4: 스플라스 리솜 워터파크 | M4: 충남 예산군 덕산면 온천단지3로 45-7
A5: 충남 | B5: 326150 | C5: 워터파크 | D5: 태안 | E5: 아일랜드 리솜 오아식스 선셋스파 | F5: 40000 | G5: 34500 | H5: 14 | I5: 대인이용권 아일랜드리솜(8/24~10/31) | J5: 즉시발송 | K5: 플레이스토리 | L5: 아일랜드 리솜 오아식스 선셋스파 | M5: 충남 태안군 안면읍 꽃지해안로 204
A6: 충남 | B6: 326465 | C6: 워터파크 | D6: 아산 | E6: 파라다이스 스파 도고 | F6: 55000 | G6: 28900 | H6: 47 | I6: 로우시즌 종일권 스파 도고(9/1~12/17) | J6: 즉시발송 | K6: 파라다이스 스파 도고 | L6: 파라다이스스파도고 | M6: 충남 아산시 도고면 도고온천로 176
A7: 충남 | B7: 328481 | C7: 숙박 | D7: 아산 | E7: 파라다이스 스파도고 캐빈파크 | F7: 160000 | G7: 156000 | H7: 3 | I7: 디럭스 주중 하반기 로우시즌 ROOM ONLY 파라다이스스파도고캐빈파크 | J7: 예약대기 | K7: LMS 문자 | L7: 파라다이스 스파도고 | M7: 충청남도 아산시 도고면 도고온천로 176
A8: 충남 | B8: 329749 | C8: 테마파크 | D8: 아산 | E8: 아산공룡월드 | F8: 20000 | G8: 16200 | H8: 19 | I8: 주중·주말공통 종일권 아산공룡월드(~12/31) | J8: 즉시발송 | K8: 엘에스컴퍼니 | L8: 아산 공룡월드 | M8: 충남 아산시 둔포면 해위안길 127
A9: 충남 | B9: 327662 | C9: 테마파크 | D9: 천안 | E9: 천안 공룡월드&키즈카페 | F9: 23000 | G9: 17900 | H9: 22 | I9: 주중 종일권 천안공룡월드(~10/31) | J9: 즉시발송 | K9: 엘에스컴퍼니 | L9: 천안 공룡월드 | M9: 충남 천안시 동남구 청수11로 35 9층
A11: 전북 상품 수 | B11: =COUNTIF(상품목록!$D$2:$D$101,"*전북*")
A12: 충남 상품 수 | B12: =COUNTIF(상품목록!$D$2:$D$101,"*충남*")

Sheet 워터파크
A1: product_id | B1: region | C1: name | D1: option | E1: detail_div | F1: week_div | G1: list_price | H1: sale_price | I1: discount_pct | J1: start_date | K1: end_date | L1: issue_channel
A2: 329434 | B2: 의정부 | C2: 장암 아일랜드캐슬 워터파크 1인 종일권 | D2: (대소공통)장암 1인 종일권 (9/4~10/31)*구명조끼 미포함 | E2: 대소공통 | F2: 주중+주말 | G2: 45000 | H2: 21000 | I2: 53 | J2: 2026-09-04 | K2: 2026-10-31 | L2: LMS 문자
A3: 330442 | B3: 아산 | C3: 아산스파비스 | D3: 주중·주말공통이용권 아산스파비스(~26/12/31) | E3: 대소공통 | F3: 주중+주말 | G3: 50000 | H3: 20000 | I3: 60 | J3: 2026-09-29 | K3: 2026-12-31 | L3: LMS 문자
A4: 325961 | B4: 정선 | C4: 하이원 워터월드 | D4: 준성수기 주중 대인권 하이원워터월드(8/31~10/18) | E4: 대인 | F4: 주중 | G4: 64000 | H4: 28000 | I4: 56 | J4: 2026-08-31 | K4: 2026-10-18 | L4: 플레이스토리
A5: 325961 | B5: 정선 | C5: 하이원 워터월드 | D5: 준성수기 주중 소인권 하이원워터월드(8/31~10/18) | E5: 소인 | F5: 주중 | G5: 53000 | H5: 26000 | I5: 51 | J5: 2026-08-31 | K5: 2026-10-18 | L5: 플레이스토리
A6: 325961 | B6: 정선 | C6: 하이원 워터월드 | D6: 준성수기 주말 대인권 하이원워터월드(8/31~10/18) | E6: 대인 | F6: 주말 | G6: 64000 | H6: 31000 | I6: 52 | J6: 2026-08-31 | K6: 2026-10-18 | L6: 플레이스토리
A7: 325961 | B7: 정선 | C7: 하이원 워터월드 | D7: 준성수기 주말 소인권 하이원워터월드(8/31~10/18) | E7: 소인 | F7: 주말 | G7: 53000 | H7: 28500 | I7: 46 | J7: 2026-08-31 | K7: 2026-10-18 | L7: 플레이스토리
A8: 326087 | B8: 예산 | C8: 스플라스 리솜 워터파크 | D8: 소인입장권 스플라스 워터파크(8/24~10/31) | E8: 소인 | F8: 주중+주말 | G8: 40000 | H8: 27400 | I8: 32 | J8: 2026-08-24 | K8: 2026-10-31 | L8: 플레이스토리
A9: 326087 | B9: 예산 | C9: 스플라스 리솜 워터파크 | D9: 대인입장권 스플라스 워터파크(8/24~10/31) | E9: 대인 | F9: 주중+주말 | G9: 55000 | H9: 37800 | I9: 31 | J9: 2026-08-24 | K9: 2026-10-31 | L9: 플레이스토리
A10: 326024 | B10: 제천 | C10: 포레스트 리솜 해브나인 웰니스 스파 | D10: 소인이용권 포레스트리솜(8/24~10/31) | E10: 소인 | F10: 주중+주말 | G10: 45000 | H10: 31000 | I10: 31 | J10: 2026-08-24 | K10: 2026-10-31 | L10: 플레이스토리
A11: 326024 | B11: 제천 | C11: 포레스트 리솜 해브나인 웰니스 스파 | D11: 대인이용권 포레스트리솜(8/24~10/31) | E11: 대인 | F11: 주중+주말 | G11: 60000 | H11: 41200 | I11: 31 | J11: 2026-08-24 | K11: 2026-10-31 | L11: 플레이스토리
A12: 326150 | B12: 태안 | C12: 아일랜드 리솜 오아식스 선셋스파 | D12: 대인이용권 아일랜드리솜(8/24~10/31) | E12: 대인 | F12: 주중+주말 | G12: 40000 | H12: 34500 | I12: 14 | J12: 2026-08-24 | K12: 2026-10-31 | L12: 플레이스토리
A13: 326465 | B13: 아산 | C13: 파라다이스 스파 도고 | D13: 로우시즌 종일권 스파 도고(9/1~12/17) | E13: 대소공통 | F13: 주중+주말 | G13: 55000 | H13: 28900 | I13: 47 | J13: 2026-09-01 | K13: 2026-12-17 | L13: 파라다이스 스파 도고
... A43: 328292 | B43: 부산 | C43: 센텀 스파랜드 | D43: 4시간이용권 센텀스파랜드(~10/29) | E43: 대소공통 | F43: 주중+주말 | G43: 26000 | H43: 20500 | I43: 21 | J43: 2026-07-01 | K43: 2026-10-29 | L43: LMS 문자/순차 발송
A45: 과거 매출 상위 10곳 | B45: 검색어(상품명) | C45: 판매 상품 수 | D45: 판매 여부
A46: 원마운트 | B46: 원마운트 | C46: =COUNTIFS(상품목록!$G$2:$G$101,"*"&B46&"*",상품목록!$B$2:$B$101,"워터파크") | D46: =IF(C46>0,"판매 중","미판매")
A47: 테르메덴 | B47: 테르메덴 | C47: =COUNTIFS(상품목록!$G$2:$G$101,"*"&B47&"*",상품목록!$B$2:$B$101,"워터파크") | D47: =IF(C47>0,"판매 중","미판매")
A48: 파라다이스 스파도고 | B48: 스파 도고 | C48: =COUNTIFS(상품목록!$G$2:$G$101,"*"&B48&"*",상품목록!$B$2:$B$101,"워터파크") | D48: =IF(C48>0,"판매 중","미판매")
A49: 아산스파비스 | B49: 스파비스 | C49: =COUNTIFS(상품목록!$G$2:$G$101,"*"&B49&"*",상품목록!$B$2:$B$101,"워터파크") | D49: =IF(C49>0,"판매 중","미판매")
A50: 웅진플레이도시 | B50: 웅진플레이도시 | C50: =COUNTIFS(상품목록!$G$2:$G$101,"*"&B50&"*",상품목록!$B$2:$B$101,"워터파크") | D50: =IF(C50>0,"판매 중","미판매")
A51: 씨랄라 | B51: 씨랄라 | C51: =COUNTIFS(상품목록!$G$2:$G$101,"*"&B51&"*",상품목록!$B$2:$B$101,"워터파크") | D51: =IF(C51>0,"판매 중","미판매")
A52: 썬밸리 | B52: 썬밸리 | C52: =COUNTIFS(상품목록!$G$2:$G$101,"*"&B52&"*",상품목록!$B$2:$B$101,"워터파크") | D52: =IF(C52>0,"판매 중","미판매")
A53: 아쿠아필드 | B53: 아쿠아필드 | C53: =COUNTIFS(상품목록!$G$2:$G$101,"*"&B53&"*",상품목록!$B$2:$B$101,"워터파크") | D53: =IF(C53>0,"판매 중","미판매")
A54: 스플라스리솜 | B54: 스플라스 | C54: =COUNTIFS(상품목록!$G$2:$G$101,"*"&B54&"*",상품목록!$B$2:$B$101,"워터파크") | D54: =IF(C54>0,"판매 중","미판매")
A55: 포레스트리솜 | B55: 포레스트 리솜 | C55: =COUNTIFS(상품목록!$G$2:$G$101,"*"&B55&"*",상품목록!$B$2:$B$101,"워터파크") | D55: =IF(C55>0,"판매 중","미판매")
A57: 판매 상품 수 = 상품목록에서 cat1=워터파크이고 name에 검색어가 들어간 상품 수(수식). 과거 매출 순위는 작업지시서 제공 정보.

Sheet 발권대행사
A1: 발송채널(issue_channel) | B1: 상품 수 | C1: 비중 | D1: 즉시발송 | E1: 예약필수 | F1: 예약대기 | G1: 평균 할인율(%)
A2: H2OKR | B2: =COUNTIF(상품목록!$S$2:$S$101,A2) | C2: =B2/COUNTA(상품목록!$A$2:$A$101) | D2: =COUNTIFS(상품목록!$S$2:$S$101,A2,상품목록!$R$2:$R$101,"즉시발송") | E2: =COUNTIFS(상품목록!$S$2:$S$101,A2,상품목록!$R$2:$R$101,"예약필수") | F2: =COUNTIFS(상품목록!$S$2:$S$101,A2,상품목록!$R$2:$R$101,"예약대기") | G2: =IFERROR(ROUND(AVERAGEIFS(상품목록!$K$2:$K$101,상품목록!$S$2:$S$101,A2,상품목록!$AC$2:$AC$101,"Y"),1),"-")
